Workbook

Sheet KK
A1: date | B1: Yb/Sr_ErYb_mean | C1: Yb/Sr_ErYb_err | D1: Yb/Sr_TiSa_mean | E1: Yb/Sr_TiSa_err | F1: Al/Yb_ErYb_mean | G1: Al/Yb_ErYb_err | H1: Al/Yb_TiSa_mean | I1: Al/Yb_TiSa_err | J1: Al/Sr_ErYb_mean | K1: Al/Sr_ErYb_err | L1: Al/Sr_TiSa_mean | M1: Al/Sr_TiSa_err | N1: Yb/Sr_comb_combined
A2: 45406 | B2: -1.072e-16 | C2: 7.5e-18 | F2: -2.647e-17 | G2: 1.8e-16 | J2: -1.164e-16 | K2: 2e-16
A3: 45408 | B3: -1.089e-16 | C3: 9e-18 | D3: -1.076e-16 | E3: 1e-17 | F3: 2.292e-17 | G3: 5e-17 | J3: -8.769e-17 | K3: 5e-17
A4: 45456 | B4: -1.167e-16 | C4: 4e-18 | D4: -1.179e-16 | E4: 4e-18
A5: 45489 | B5: -1.264e-16 | C5: 4e-18 | D5: -1.267e-16 | E5: 4e-18
A6: 45490 | B6: -1.257e-16 | C6: 3e-18 | D6: -1.256e-16 | E6: 3e-18
A7: 45517 | B7: -1.085e-16 | C7: 3e-18 | D7: -1.1e-16 | E7: 3e-18 | F7: -1.92e-17 | G7: 7e-18 | H7: 6.7e-18 | I7: 6.7e-18 | J7: -1.286e-16 | K7: 8e-18 | L7: -1.277e-16 | M7: 7.75e-18
A8: 45616 | B8: -9.912e-17 | C8: 7.794e-18 | D8: -9.829e-17 | E8: 7.952e-18
A9: 45616 | B9: -9.379e-17 | C9: 2.824e-18 | D9: -9.301e-17 | E9: 2.87e-18
A10: 45639 | B10: -1.115e-16 | C10: 3e-18 | D10: -1.109e-16 | E10: 3e-18
A11: 45642 | B11: -1.105e-16 | C11: 2.3e-18 | D11: -1.088e-16 | E11: 2.2e-18
A12: 45673 | B12: -1.0049656e-16 | C12: 1.2477037e-18 | D12: -9.9401081e-17 | E12: 1.1418118e-18 | F12: -3.152e-17 | G12: 5.6651496e-18 | J12: -1.352e-16 | K12: 5.5631142e-18
A13: 45681 | B13: -9.6939414e-17 | C13: 1.3773921e-18 | D13: -9.6587145e-17 | E13: 1.7342852e-18 | F13: -8.691e-18 | G13: 4.793005e-18 | H13: -3.511e-17 | I13: 7.9639768e-18 | J13: -1.139e-16 | K13: 4.793005e-18 | L13: -1.254e-16 | M13: 5.9901275e-18
A14: 45692 | B14: -1.047659e-16 | C14: 1.0195212e-18 | D14: -1.0424326e-16 | E14: 1.1846306e-18 | F14: -1.626e-17 | G14: 3.0030574e-18 | H14: -1.691e-17 | I14: 3.0222035e-18 | J14: -1.265e-16 | K14: 3.1515935e-18 | L14: -1.264e-16 | M14: 3.1515935e-18
A15: 45694 | B15: -1.0302409e-16 | C15: 1.2812243e-18 | D15: -1.0257938e-16 | E15: 1.3330176e-18 | F15: -1.748e-17 | G15: 3.4647779e-18 | H15: -1.699e-17 | I15: 3.466754e-18 | J15: -1.28e-16 | K15: 2.718197e-18 | L15: -1.274e-16 | M15: 2.7944956e-18
A16: 45715 | B16: -1.0713893e-16 | C16: 1.0488356e-18 | D16: -1.0753248e-16 | E16: 1.1042559e-18 | F16: -1.6184407e-17 | G16: 2.9193548e-18 | H16: -1.6542776e-17 | I16: 3.2059893e-18 | J16: -1.2304992e-16 | K16: 3.0639514e-18 | L16: -1.2398135e-16 | M16: 3.353135e-18
A17: 45716 | B17: -1.0257183e-16 | C17: 1.1149989e-18 | D17: -1.0223189e-16 | E17: 1.0886766e-18 | F17: -1.0455233e-17 | G17: 3.2318291e-18 | H17: -1.0989984e-17 | I17: 3.2414528e-18 | J17: -1.1392217e-16 | K17: 2.8588836e-18 | L17: -1.1357231e-16 | M17: 2.8742788e-18
A18: 45720 | B18: -1.036598e-16 | C18: 1.0247416e-18 | D18: -1.0329814e-16 | E18: 1.0243738e-18 | F18: -1.514275e-17 | G18: 3.7435965e-18 | H18: -1.5014852e-17 | I18: 3.7663451e-18 | J18: -1.1891699e-16 | K18: 3.7910201e-18 | L18: -1.1858199e-16 | M18: 3.7966518e-18
A19: 45722 | B19: -1.0431842e-16 | C19: 1.2315544e-18 | D19: -1.034513e-16 | E19: 1.2484873e-18 | F19: -1.5396099e-17 | G19: 3.7916192e-18 | H19: -1.5555518e-17 | I19: 3.7924037e-18 | J19: -1.207086e-16 | K19: 4.187164e-18 | L19: -1.2024797e-16 | M19: 4.1692706e-18
A20: 45723 | B20: -1.026384e-16 | C20: 1.4419732e-18 | D20: -1.0199616e-16 | E20: 1.4732846e-18 | F20: -2.4808255e-17 | G20: 4.1794225e-18 | H20: -2.4816121e-17 | I20: 4.1854348e-18 | J20: -1.2648189e-16 | K20: 2.9181295e-18 | L20: -1.2539144e-16 | M20: 2.886708e-18
A21: 45729 | B21: -1.0636057e-16 | C21: 1.1043006e-18 | D21: -1.0655746e-16 | E21: 1.1245547e-18 | F21: -1.45987e-17 | G21: 3.7445246e-18 | H21: -1.4436537e-17 | I21: 3.7086633e-18 | J21: -1.2040126e-16 | K21: 3.2257535e-18 | L21: -1.2014356e-16 | M21: 3.2228834e-18
A22: 45734 | B22: -1.0452321e-16 | C22: 1.2224334e-18 | D22: -1.0386003e-16 | E22: 1.2793367e-18 | F22: -1.5312419e-17 | G22: 5.5379658e-18 | H22: -1.5280215e-17 | I22: 5.5825565e-18 | J22: -1.1811883e-16 | K22: 7.1254864e-18 | L22: -1.1802542e-16 | M22: 7.1877624e-18
A23: 45736 | B23: -1.0675694e-16 | C23: 9.3143133e-19 | D23: -1.0640807e-16 | E23: 9.5788699e-19 | F23: -1.5658075e-17 | G23: 3.042072e-18 | H23: -1.6900394e-17 | I23: 3.0293542e-18 | J23: -1.2276979e-16 | K23: 3.0205525e-18 | L23: -1.2337484e-16 | M23: 3.0702777e-18
A24: 45737 | B24: -1.0788008e-16 | C24: 1.0979454e-18 | D24: -1.0741009e-16 | E24: 1.2155386e-18 | F24: -1.0210855e-17 | G24: 3.7900407e-18 | H24: -9.4218974e-18 | I24: 4.0319885e-18 | J24: -1.1974242e-16 | K24: 3.5622022e-18 | L24: -1.1911331e-16 | M24: 3.9816755e-18

Sheet NN
A1: date | B1: Yb/Sr_ErYb_mean | C1: Yb/Sr_ErYb_err | D1: Yb/Sr_TiSa_mean | E1: Yb/Sr_TiSa_err | F1: Al/Yb_ErYb_mean | G1: Al/Yb_ErYb_err | H1: Al/Yb_TiSa_mean | I1: Al/Yb_TiSa_err | J1: Al/Sr_ErYb_mean | K1: Al/Sr_ErYb_err | L1: Al/Sr_TiSa_mean | M1: Al/Sr_TiSa_err
A2: 45406 | B2: -1.08807e-16 | C2: 6.36e-18 | F2: 3.63755e-17 | G2: 5.26e-17 | J2: -6.14532e-17 | K2: 4.61e-17 | L2: -6.70415e-17 | M2: 4.47e-17
A3: 45408 | B3: -1.08919e-16 | C3: 8e-18 | D3: -1.08523e-16 | E3: 7.45e-18 | F3: 2.12847e-17 | G3: 3.54e-17 | H3: 1.53786e-17 | I3: 3.6e-17 | J3: -8.90212e-17 | K3: 3.21e-17 | L3: -9.48802e-17 | M3: 3.32e-17
A4: 45456 | B4: -1.16847e-16 | C4: 3.14e-18 | D4: -1.19005e-16 | E4: 3.11e-18
A5: 45489 | B5: -1.27072e-16 | C5: 2.36e-18 | D5: -1.26908e-16 | E5: 2.36e-18
A6: 45490 | B6: -1.25208e-16 | C6: 1.47e-18 | D6: -1.25076e-16 | E6: 1.5e-18
A7: 45517 | B7: -1.09738e-16 | C7: 1.89e-18 | D7: -1.09925e-16 | E7: 1.88e-18 | F7: -1.83954e-17 | G7: 5.33e-18 | H7: -1.89619e-17 | I7: 5.37e-18 | J7: -1.27911e-16 | K7: 5.68e-18 | L7: -1.28358e-16 | M7: 5.71e-18
A8: 45616 | B8: -9.90122e-17 | C8: 4.69e-18 | D8: -9.90019e-17 | E8: 4.73e-18
A9: 45616 | B9: -9.36243e-17 | C9: 2.79e-18 | D9: -9.3761e-17 | E9: 2.82e-18
A10: 45639 | B10: -1.11198e-16 | C10: 2.17e-18 | D10: -1.11237e-16 | E10: 2.14e-18
A11: 45642 | B11: -1.10399e-16 | C11: 1.75e-18 | D11: -1.10367e-16 | E11: 1.73e-18
A12: 45673 | B12: -1.0043e-16 | C12: 1.21e-18 | D12: -1.0051e-16 | E12: 1.2e-18 | F12: -3.4334e-17 | G12: 6.46e-18 | J12: -1.3498e-16 | K12: 5.88e-18
A13: 45681 | B13: -9.6948e-17 | C13: 1.58e-18 | D13: -9.7543e-17 | E13: 1.9e-18 | F13: -1.2884e-17 | G13: 8.34e-18 | H13: -3.8628e-17 | I13: 1.17e-17 | J13: -1.1402e-16 | K13: 5.5e-18 | L13: -1.2622e-16 | M13: 7.45e-18
A14: 45692 | B14: -1.0455e-16 | C14: 1.03e-18 | D14: -1.0453e-16 | E14: 1.08e-18 | F14: -2.2251e-17 | G14: 3.78e-18 | H14: -2.2842e-17 | I14: 3.65e-18 | J14: -1.2569e-16 | K14: 3.29e-18 | L14: -1.2641e-16 | M14: 3.94e-18
A15: 45694 | B15: -1.0297e-16 | C15: 1.56e-18 | D15: -1.0348e-16 | E15: 1.61e-18 | F15: -2.2105e-17 | G15: 3.62e-18 | H15: -2.155e-17 | I15: 3.61e-18 | J15: -1.2805e-16 | K15: 2.83e-18 | L15: -1.2809e-16 | M15: 2.84e-18
A16: 45715 | B16: -1.0693e-16 | C16: 1.31e-18 | D16: -1.0753e-16 | E16: 1.3e-18 | F16: -1.6067e-17 | G16: 3.37e-18 | H16: -1.6345e-17 | I16: 3.48e-18 | J16: -1.2271e-16 | K16: 3.48e-18 | L16: -1.239e-16 | M16: 3.61e-18
A17: 45716 | B17: -1.0246e-16 | C17: 1.15e-18 | D17: -1.0273e-16 | E17: 1.12e-18 | F17: -1.0398e-17 | G17: 3.78e-18 | H17: -1.0843e-17 | I17: 3.77e-18 | J17: -1.1386e-16 | K17: 2.88e-18 | L17: -1.1438e-16 | M17: 2.89e-18
A18: 45720 | B18: -1.036e-16 | C18: 1.07e-18 | D18: -1.0357e-16 | E18: 1.07e-18 | F18: -1.517e-17 | G18: 4.25e-18 | H18: -1.4958e-17 | I18: 4.26e-18 | J18: -1.1888e-16 | K18: 4.23e-18 | L18: -1.1867e-16 | M18: 4.25e-18
A19: 45722 | B19: -1.043e-16 | C19: 1.36e-18 | D19: -1.0428e-16 | E19: 1.36e-18 | F19: -1.4372e-17 | G19: 4.72e-18 | H19: -1.4557e-17 | I19: 4.72e-18 | J19: -1.2171e-16 | K19: 4.68e-18 | L19: -1.2194e-16 | M19: 4.67e-18
A20: 45723 | B20: -1.0253e-16 | C20: 1.59e-18 | D20: -1.0209e-16 | E20: 1.58e-18 | F20: -2.4903e-17 | G20: 4.78e-18 | H20: -2.4845e-17 | I20: 4.69e-18 | J20: -1.2558e-16 | K20: 3.48e-18 | L20: -1.2495e-16 | M20: 3.41e-18
A21: 45729 | B21: -1.0634e-16 | C21: 1.15e-18 | D21: -1.066e-16 | E21: 1.17e-18 | F21: -1.4676e-17 | G21: 3.8e-18 | H21: -1.4406e-17 | I21: 3.77e-18 | J21: -1.2191e-16 | K21: 3.66e-18 | L21: -1.2169e-16 | M21: 3.62e-18
A22: 45734 | B22: -1.0424e-16 | C22: 1.47e-18 | D22: -1.0422e-16 | E22: 1.5e-18 | F22: -1.5371e-17 | G22: 5.73e-18 | H22: -1.5301e-17 | I22: 5.81e-18 | J22: -1.181e-16 | K22: 8.27e-18 | L22: -1.1816e-16 | M22: 8.4e-18
A23: 45736 | B23: -1.0674e-16 | C23: 1.1e-18 | D23: -1.0662e-16 | E23: 1.11e-18 | F23: -1.5624e-17 | G23: 3.66e-18 | H23: -1.6854e-17 | I23: 3.54e-18 | J23: -1.2211e-16 | K23: 3.5e-18 | L23: -1.233e-16 | M23: 3.42e-18
A24: 45737 | B24: -1.0785e-16 | C24: 1.18e-18 | D24: -1.0795e-16 | E24: 1.49e-18 | F24: -1.0207e-17 | G24: 3.94e-18 | H24: -9.4878e-18 | I24: 3.83e-18 | J24: -1.2048e-16 | K24: 3.95e-18 | L24: -1.2048e-16 | M24: 3.95e-18

Sheet JS YbReRunShifts
A1: date | B1: Yb/Sr_ErYb_mean | C1: Yb/Sr_ErYb_err | D1: Yb/Sr_TiSa_mean | E1: Yb/Sr_TiSa_err | F1: Al/Yb_ErYb_mean | G1: Al/Yb_ErYb_err | H1: Al/Yb_TiSa_mean | I1: Al/Yb_TiSa_err | J1: Al/Sr_ErYb_mean | K1: Al/Sr_ErYb_err | L1: Al/Sr_TiSa_mean | M1: Al/Sr_TiSa_err
A2: 45673 | B2: -1.0034906e-16 | C2: 1.51e-18 | F2: -3.4451554e-17 | G2: 8.62e-18 | J2: -1.350916e-16 | K2: 8.09e-18
A3: 45681 | B3: -9.6596607e-17 | C3: 1.54e-18 | D3: -9.692353e-17 | E3: 2.12e-18 | F3: -1.290289e-17 | G3: 1.208e-17 | H3: -3.8264619e-17 | I3: 1.247e-17 | J3: -1.1406294e-16 | K3: 7.26e-18 | L3: -1.2529145e-16 | M3: 9.08e-18
A4: 45692 | B4: -1.0453039e-16 | C4: 1.24e-18 | D4: -1.0410572e-16 | E4: 1.31e-18 | F4: -2.2347735e-17 | G4: 4.46e-18 | H4: -2.2868017e-17 | I4: 4.51e-18 | J4: -1.2576081e-16 | K4: 4.6e-18 | L4: -1.2595569e-16 | M4: 4.63e-18
A5: 45694 | B5: -1.0293958e-16 | C5: 1.6e-18 | D5: -1.0251712e-16 | E5: 1.65e-18 | F5: -2.2216084e-17 | G5: 5.03e-18 | H5: -2.15931e-17 | I5: 5.03e-18 | J5: -1.2810471e-16 | K5: 3.76e-18 | L5: -1.2707733e-16 | M5: 3.78e-18
A6: 45715 | B6: -1.0689003e-16 | C6: 1.36e-18 | D6: -1.0714631e-16 | E6: 1.36e-18 | F6: -1.6175446e-17 | G6: 4.27e-18 | H6: -1.636229e-17 | I6: 4.66e-18 | J6: -1.2278058e-16 | K6: 4.44e-18 | L6: -1.2350976e-16 | M6: 4.42e-18
A7: 45716 | B7: -1.0243451e-16 | C7: 1.33e-18 | D7: -1.0198789e-16 | E7: 1.33e-18 | F7: -1.0511552e-17 | G7: 4.44e-18 | H7: -1.0869698e-17 | I7: 4.44e-18 | J7: -1.1378995e-16 | K7: 4.02e-18 | L7: -1.1349519e-16 | M7: 4.06e-18
A8: 45720 | B8: -1.0358411e-16 | C8: 1.22e-18 | D8: -1.033932e-16 | E8: 1.23e-18 | F8: -1.5278574e-17 | G8: 5.22e-18 | H8: -1.4978383e-17 | I8: 5.26e-18 | J8: -1.1897136e-16 | K8: 5.25e-18 | L8: -1.1860651e-16 | M8: 5.28e-18
A9: 45722 | B9: -1.0426846e-16 | C9: 2.3e-18 | D9: -1.0340824e-16 | E9: 2.3e-18 | F9: -1.5384074e-17 | G9: 5.35e-18 | H9: -1.5404422e-17 | I9: 5.36e-18 | J9: -1.2179797e-16 | K9: 5.42e-18 | L9: -1.211671e-16 | M9: 5.43e-18
A10: 45723 | B10: -1.0248672e-16 | C10: 1.63e-18 | D10: -1.0204438e-16 | E10: 1.64e-18 | F10: -2.5012426e-17 | G10: 6.08e-18 | H10: -2.4872222e-17 | I10: 6.01e-18 | J10: -1.2570331e-16 | K10: 4.25e-18 | L10: -1.246431e-16 | M10: 4.22e-18
A11: 45729 | B11: -1.0590373e-16 | C11: 1.37e-18 | D11: -1.0606374e-16 | E11: 1.38e-18 | F11: -1.4758677e-17 | G11: 5.23e-18 | H11: -1.4413867e-17 | I11: 5.17e-18 | J11: -1.1953674e-16 | K11: 4.2e-18 | L11: -1.1953674e-16 | M11: 4.21e-18
A12: 45734 | B12: -1.0427039e-16 | C12: 2.7e-18 | D12: -1.0344582e-16 | E12: 2.7e-18 | F12: -1.5307904e-17 | G12: 7.82e-18 | H12: -1.5437646e-17 | I12: 7.91e-18 | J12: -1.1816221e-16 | K12: 9.66e-18 | L12: -1.1799689e-16 | M12: 9.82e-18
A13: 45736 | B13: -1.0670724e-16 | C13: 1.115e-18 | D13: -1.0641252e-16 | E13: 1.2e-18 | F13: -1.522815e-17 | G13: 4.23e-18 | H13: -1.6325637e-17 | I13: 4.19e-18 | J13: -1.2257157e-16 | K13: 4.174e-18 | L13: -1.2353961e-16 | M13: 4.19e-18
A14: 45737 | B14: -1.0787879e-16 | C14: 1.4e-18 | D14: -1.0780138e-16 | E14: 1.55e-18 | F14: -1.0309672e-17 | G14: 5.1e-18 | H14: -9.5110742e-18 | I14: 5.3e-18 | J14: -1.2188836e-16 | K14: 4.11e-18 | L14: -1.2161388e-16 | M14: 4.12e-18

Sheet MCM
A1: date | B1: Yb/Sr_ErYb_mean | C1: Yb/Sr_ErYb_err | D1: Yb/Sr_TiSa_mean | E1: Yb/Sr_TiSa_err | F1: Al/Yb_ErYb_mean | G1: Al/Yb_ErYb_err | H1: Al/Yb_TiSa_mean | I1: Al/Yb_TiSa_err | J1: Al/Sr_ErYb_mean | K1: Al/Sr_ErYb_err | L1: Al/Sr_TiSa_mean | M1: Al/Sr_TiSa_err
A2: 45406
A3: 45408
A4: 45456
A5: 45489
A6: 45490
A7: 45517
A8: 45616
A9: 45616
A10: 45639
A11: 45642
A12: 45673
A13: 45681
... A15: 45694
A16: 45715 | B16: -1.0755e-16 | C16: 1.0529e-18 | D16: -1.0815e-16 | E16: 1.05e-18 | F16: -1.669e-17 | G16: 2.874e-18 | H16: -1.6975e-17 | I16: 3.117e-18 | J16: -1.2311e-16 | K16: 2.981e-18 | L16: -1.2464e-16 | M16: 3.234e-18
A17: 45716 | B17: -1.03e-16 | C17: 1.0874e-18 | D17: -1.0327e-16 | E17: 1.07e-18 | F17: -1.1031e-17 | G17: 3.114e-18 | H17: -1.1478e-17 | I17: 3.062e-18 | J17: -1.1457e-16 | K17: 2.855e-18 | L17: -1.1506e-16 | M17: 2.772e-18
A18: 45720 | B18: -1.0429e-16 | C18: 1.0758e-18 | D18: -1.0427e-16 | E18: 1.081e-18 | F18: -1.5568e-17 | G18: 3.556e-18 | H18: -1.5357e-17 | I18: 3.602e-18 | J18: -1.1944e-16 | K18: 3.534e-18 | L18: -1.1975e-16 | M18: 3.585e-18
A19: 45722 | B19: -1.0507e-16 | C19: 1.3535e-18 | D19: -1.0507e-16 | E19: 1.377e-18 | F19: -1.5694e-17 | G19: 3.804e-18 | H19: -1.5801e-17 | I19: 3.794e-18 | J19: -1.2245e-16 | K19: 3.805e-18 | L19: -1.2261e-16 | M19: 3.805e-18
A20: 45723 | B20: -1.0318e-16 | C20: 1.417e-18 | D20: -1.0281e-16 | E20: 1.433e-18 | F20: -2.542e-17 | G20: 4.347e-18 | H20: -2.5359e-17 | I20: 4.411e-18 | J20: -1.2619e-16 | K20: 3.023e-18 | L20: -1.2526e-16 | M20: 3.026e-18
A21: 45729 | B21: -1.06608e-16 | C21: 1.035398e-18 | D21: -1.0692e-16 | E21: 1.039e-18 | F21: -1.4987e-17 | G21: 3.526e-18 | H21: -1.4704e-17 | I21: 3.481e-18 | J21: -1.2026e-16 | K21: 2.837e-18 | L21: -1.1997e-16 | M21: 2.853e-18
A22: 45734 | B22: -1.0468e-16 | C22: 1.32102e-18 | D22: -1.0464e-16 | E22: 1.336e-18 | F22: -1.5762e-17 | G22: 5.796e-18 | H22: -1.5693e-17 | I22: 5.831e-18 | J22: -1.1811e-16 | K22: 7.408e-18 | L22: -1.181e-16 | M22: 7.519e-18
A23: 45736 | B23: -1.0708e-16 | C23: 8.71033e-19 | D23: -1.0699e-16 | E23: 9.18e-19 | F23: -1.5513e-17 | G23: 2.791e-18 | H23: -1.6697e-17 | I23: 2.774e-18 | J23: -1.21907e-16 | K23: 2.723e-18 | L23: -1.2366e-16 | M23: 2.755e-18
A24: 45737 | B24: -1.0847e-16 | C24: 9.99025e-19 | D24: -1.0867e-16 | E24: 1.17e-18 | F24: -1.0617e-17 | G24: 3.802e-18 | H24: -9.503e-18 | I24: 4.076e-18 | J24: -1.2166e-16 | K24: 2.958e-18 | L24: -1.2165e-16 | M24: 2.94e-18
B25: =SUMPRODUCT(MCM!B16:B24,1/MCM!C16:C24^2)/SUM(1/MCM!C16:C24^2) -> #VALUE! | D25: =SUMPRODUCT(MCM!D16:D24,1/MCM!E16:E24^2)/SUM(1/MCM!E16:E24^2) -> #VALUE! | F25: =SUMPRODUCT(MCM!F16:F24,1/MCM!G16:G24^2)/SUM(1/MCM!G16:G24^2) -> #VALUE! | H25: =SUMPRODUCT(MCM!H16:H24,1/MCM!I16:I24^2)/SUM(1/MCM!I16:I24^2) -> #VALUE! | J25: =SUMPRODUCT(MCM!J16:J24,1/MCM!K16:K24^2)/SUM(1/MCM!K16:K24^2) -> #VALUE! | L25: =SUMPRODUCT(MCM!L16:L24,1/MCM!M16:M24^2)/SUM(1/MCM!M16:M24^2) -> #VALUE!
D26: =B25-D25 -> #VALUE! | H26: =F25-H25 -> #VALUE! | L26: =J25-L25 -> #VALUE!

Sheet Diffs
A1: date | B1: Yb/Sr_ErYb_mean | C1: Yb/Sr_ErYb_err | D1: Yb/Sr_TiSa_mean | E1: Yb/Sr_TiSa_err | F1: Al/Yb_ErYb_mean | G1: Al/Yb_ErYb_err | H1: Al/Yb_TiSa_mean | I1: Al/Yb_TiSa_err | J1: Al/Sr_ErYb_mean | K1: Al/Sr_ErYb_err | L1: Al/Sr_TiSa_mean | M1: Al/Sr_TiSa_err | N1: MCM-KK | P1: date | Q1: Yb/Sr_ErYb_mean | R1: Yb/Sr_ErYb_err | S1: Yb/Sr_TiSa_mean | T1: Yb/Sr_TiSa_err | U1: Al/Yb_ErYb_mean | V1: Al/Yb_ErYb_err | W1: Al/Yb_TiSa_mean | X1: Al/Yb_TiSa_err | Y1: Al/Sr_ErYb_mean | Z1: Al/Sr_ErYb_err | AA1: Al/Sr_TiSa_mean | AB1: Al/Sr_TiSa_err | AC1: MCM-NN
A2: 45715 | B2: =MCM!B$16-KK!B$16 -> -4.1106597e-19 | C2: =SQRT(MCM!C16^2+KK!C16^2) -> 1.4861542e-18 | D2: =MCM!D16-KK!D16 -> -6.1751979e-19 | E2: =SQRT(MCM!E16^2+KK!E16^2) -> 1.523772e-18 | F2: =MCM!F16-KK!F16 -> -5.0559295e-19 | G2: =SQRT(MCM!G16^2+KK!G16^2) -> 4.096646e-18 | H2: =MCM!H16-KK!H16 -> -4.3222415e-19 | I2: =SQRT(MCM!I16^2+KK!I16^2) -> 4.4714714e-18 | J2: =MCM!J16-KK!J16 -> -6.0077862e-20 | K2: =SQRT(MCM!K16^2+KK!K16^2) -> 4.2748286e-18 | L2: =MCM!L16-KK!L16 -> -6.5864757e-19 | M2: =SQRT(MCM!M16^2+KK!M16^2) -> 4.6585695e-18 | P2: 45715 | Q2: =MCM!B16-NN!B16 -> -6.2e-19 | R2: =MCM!C16-NN!C16 -> -2.571e-19 | S2: =MCM!D16-NN!D16 -> -6.2e-19 | T2: =MCM!E16-NN!E16 -> -2.5e-19 | U2: =MCM!F16-NN!F16 -> -6.23e-19 | V2: =MCM!G16-NN!G16 -> -4.96e-19 | W2: =MCM!H16-NN!H16 -> -6.3e-19 | X2: =MCM!I16-NN!I16 -> -3.63e-19 | ... AB2: =MCM!M16-NN!M16 -> -3.76e-19
A3: 45716 | B3: =MCM!B17-KK!B17 -> -4.2816836e-19 | C3: =SQRT(MCM!C17^2+KK!C17^2) -> 1.5574534e-18 | D3: =MCM!D17-KK!D17 -> -1.0381091e-18 | E3: =SQRT(MCM!E17^2+KK!E17^2) -> 1.526472e-18 | F3: =MCM!F17-KK!F17 -> -5.7576712e-19 | G3: =SQRT(MCM!G17^2+KK!G17^2) -> 4.4879522e-18 | H3: =MCM!H17-KK!H17 -> -4.8801614e-19 | I3: =SQRT(MCM!I17^2+KK!I17^2) -> 4.4590201e-18 | J3: =MCM!J17-KK!J17 -> -6.4783301e-19 | K3: =SQRT(MCM!K17^2+KK!K17^2) -> 4.0403268e-18 | L3: =MCM!L17-KK!L17 -> -1.4876901e-18 | M3: =SQRT(MCM!M17^2+KK!M17^2) -> 3.993177e-18 | P3: 45716 | Q3: =MCM!B17-NN!B17 -> -5.4e-19 | R3: =MCM!C17-NN!C17 -> -6.26e-20 | S3: =MCM!D17-NN!D17 -> -5.4e-19 | T3: =MCM!E17-NN!E17 -> -5e-20 | U3: =MCM!F17-NN!F17 -> -6.33e-19 | V3: =MCM!G17-NN!G17 -> -6.66e-19 | W3: =MCM!H17-NN!H17 -> -6.35e-19 | X3: =MCM!I17-NN!I17 -> -7.08e-19 | ... AB3: =MCM!M17-NN!M17 -> -1.18e-19
A4: 45720 | B4: =MCM!B18-KK!B18 -> -6.3020051e-19 | C4: =SQRT(MCM!C18^2+KK!C18^2) -> 1.485746e-18 | D4: =MCM!D18-KK!D18 -> -9.7185634e-19 | E4: =SQRT(MCM!E18^2+KK!E18^2) -> 1.4892625e-18 | F4: =MCM!F18-KK!F18 -> -4.2524963e-19 | G4: =SQRT(MCM!G18^2+KK!G18^2) -> 5.1632984e-18 | H4: =MCM!H18-KK!H18 -> -3.4214797e-19 | I4: =SQRT(MCM!I18^2+KK!I18^2) -> 5.2115026e-18 | J4: =MCM!J18-KK!J18 -> -5.2301419e-19 | K4: =SQRT(MCM!K18^2+KK!K18^2) -> 5.1827589e-18 | L4: =MCM!L18-KK!L18 -> -1.1680104e-18 | M4: =SQRT(MCM!M18^2+KK!M18^2) -> 5.2217612e-18 | P4: 45720 | Q4: =MCM!B18-NN!B18 -> -6.9e-19 | R4: =MCM!C18-NN!C18 -> 5.8e-21 | S4: =MCM!D18-NN!D18 -> -7e-19 | T4: =MCM!E18-NN!E18 -> 1.1e-20 | U4: =MCM!F18-NN!F18 -> -3.98e-19 | V4: =MCM!G18-NN!G18 -> -6.94e-19 | W4: =MCM!H18-NN!H18 -> -3.99e-19 | X4: =MCM!I18-NN!I18 -> -6.58e-19 | ... AB4: =MCM!M18-NN!M18 -> -6.65e-19
A5: 45722 | B5: =MCM!B19-KK!B19 -> -7.5158419e-19 | C5: =SQRT(MCM!C19^2+KK!C19^2) -> 1.8299422e-18 | D5: =MCM!D19-KK!D19 -> -1.6187047e-18 | E5: =SQRT(MCM!E19^2+KK!E19^2) -> 1.8587226e-18 | F5: =MCM!F19-KK!F19 -> -2.9790095e-19 | G5: =SQRT(MCM!G19^2+KK!G19^2) -> 5.370921e-18 | H5: =MCM!H19-KK!H19 -> -2.4548156e-19 | I5: =SQRT(MCM!I19^2+KK!I19^2) -> 5.3643976e-18 | J5: =MCM!J19-KK!J19 -> -1.7414e-18 | K5: =SQRT(MCM!K19^2+KK!K19^2) -> 5.6577705e-18 | L5: =MCM!L19-KK!L19 -> -2.3620346e-18 | M5: =SQRT(MCM!M19^2+KK!M19^2) -> 5.6445409e-18 | P5: 45722 | Q5: =MCM!B19-NN!B19 -> -7.7e-19 | R5: =MCM!C19-NN!C19 -> -6.5e-21 | S5: =MCM!D19-NN!D19 -> -7.9e-19 | T5: =MCM!E19-NN!E19 -> 1.7e-20 | U5: =MCM!F19-NN!F19 -> -1.322e-18 | V5: =MCM!G19-NN!G19 -> -9.16e-19 | W5: =MCM!H19-NN!H19 -> -1.244e-18 | X5: =MCM!I19-NN!I19 -> -9.26e-19 | ... AB5: =MCM!M19-NN!M19 -> -8.65e-19
A6: 45723 | B6: =MCM!B20-KK!B20 -> -5.415954e-19 | C6: =SQRT(MCM!C20^2+KK!C20^2) -> 2.0216765e-18 | D6: =MCM!D20-KK!D20 -> -8.1383683e-19 | E6: =SQRT(MCM!E20^2+KK!E20^2) -> 2.055251e-18 | F6: =MCM!F20-KK!F20 -> -6.1174542e-19 | G6: =SQRT(MCM!G20^2+KK!G20^2) -> 6.0302555e-18 | H6: =MCM!H20-KK!H20 -> -5.4287938e-19 | I6: =SQRT(MCM!I20^2+KK!I20^2) -> 6.0806896e-18 | J6: =MCM!J20-KK!J20 -> 2.9188926e-19 | K6: =SQRT(MCM!K20^2+KK!K20^2) -> 4.2016674e-18 | L6: =MCM!L20-KK!L20 -> 1.3143542e-19 | M6: =SQRT(MCM!M20^2+KK!M20^2) -> 4.1820759e-18 | P6: 45723 | Q6: =MCM!B20-NN!B20 -> -6.5e-19 | R6: =MCM!C20-NN!C20 -> -1.73e-19 | S6: =MCM!D20-NN!D20 -> -7.2e-19 | T6: =MCM!E20-NN!E20 -> -1.47e-19 | U6: =MCM!F20-NN!F20 -> -5.17e-19 | V6: =MCM!G20-NN!G20 -> -4.33e-19 | W6: =MCM!H20-NN!H20 -> -5.14e-19 | X6: =MCM!I20-NN!I20 -> -2.79e-19 | ... AB6: =MCM!M20-NN!M20 -> -3.84e-19
A7: 45729 | B7: =MCM!B21-KK!B21 -> -2.4743134e-19 | C7: =SQRT(MCM!C21^2+KK!C21^2) -> 1.5137796e-18 | D7: =MCM!D21-KK!D21 -> -3.6254058e-19 | E7: =SQRT(MCM!E21^2+KK!E21^2) -> 1.5310598e-18 | F7: =MCM!F21-KK!F21 -> -3.8829954e-19 | G7: =SQRT(MCM!G21^2+KK!G21^2) -> 5.1433589e-18 | H7: =MCM!H21-KK!H21 -> -2.674627e-19 | I7: =SQRT(MCM!I21^2+KK!I21^2) -> 5.0864078e-18 | J7: =MCM!J21-KK!J21 -> 1.4125778e-19 | K7: =SQRT(MCM!K21^2+KK!K21^2) -> 4.2958183e-18 | L7: =MCM!L21-KK!L21 -> 1.7355859e-19 | M7: =SQRT(MCM!M21^2+KK!M21^2) -> 4.3042521e-18 | P7: 45729 | Q7: =MCM!B21-NN!B21 -> -2.68e-19 | R7: =MCM!C21-NN!C21 -> -1.14602e-19 | S7: =MCM!D21-NN!D21 -> -3.2e-19 | T7: =MCM!E21-NN!E21 -> -1.31e-19 | U7: =MCM!F21-NN!F21 -> -3.11e-19 | V7: =MCM!G21-NN!G21 -> -2.74e-19 | W7: =MCM!H21-NN!H21 -> -2.98e-19 | X7: =MCM!I21-NN!I21 -> -2.89e-19 | ... AB7: =MCM!M21-NN!M21 -> -7.67e-19
A8: 45734 | B8: =MCM!B22-KK!B22 -> -1.5678802e-19 | C8: =SQRT(MCM!C22^2+KK!C22^2) -> 1.7998437e-18 | D8: =MCM!D22-KK!D22 -> -7.7996901e-19 | E8: =SQRT(MCM!E22^2+KK!E22^2) -> 1.8497563e-18 | F8: =MCM!F22-KK!F22 -> -4.4958094e-19 | G8: =SQRT(MCM!G22^2+KK!G22^2) -> 8.0164007e-18 | H8: =MCM!H22-KK!H22 -> -4.1278511e-19 | I8: =SQRT(MCM!I22^2+KK!I22^2) -> 8.0725149e-18 | J8: =MCM!J22-KK!J22 -> 8.8251515e-21 | K8: =SQRT(MCM!K22^2+KK!K22^2) -> 1.0278668e-17 | L8: =MCM!L22-KK!L22 -> -7.4581626e-20 | M8: =SQRT(MCM!M22^2+KK!M22^2) -> 1.0401889e-17 | P8: 45734 | Q8: =MCM!B22-NN!B22 -> -4.4e-19 | R8: =MCM!C22-NN!C22 -> -1.4898e-19 | S8: =MCM!D22-NN!D22 -> -4.2e-19 | T8: =MCM!E22-NN!E22 -> -1.64e-19 | U8: =MCM!F22-NN!F22 -> -3.91e-19 | V8: =MCM!G22-NN!G22 -> 6.6e-20 | W8: =MCM!H22-NN!H22 -> -3.92e-19 | X8: =MCM!I22-NN!I22 -> 2.1e-20 | ... AB8: =MCM!M22-NN!M22 -> -8.81e-19
A9: 45736 | B9: =MCM!B23-KK!B23 -> -3.2306293e-19 | C9: =SQRT(MCM!C23^2+KK!C23^2) -> 1.2752501e-18 | D9: =MCM!D23-KK!D23 -> -5.8192618e-19 | E9: =SQRT(MCM!E23^2+KK!E23^2) -> 1.3267522e-18 | F9: =MCM!F23-KK!F23 -> 1.4507489e-19 | G9: =SQRT(MCM!G23^2+KK!G23^2) -> 4.1284238e-18 | H9: =MCM!H23-KK!H23 -> 2.0339356e-19 | I9: =SQRT(MCM!I23^2+KK!I23^2) -> 4.1075616e-18 | J9: =MCM!J23-KK!J23 -> 8.6279392e-19 | K9: =SQRT(MCM!K23^2+KK!K23^2) -> 4.0667513e-18 | L9: =MCM!L23-KK!L23 -> -2.8516151e-19 | M9: =SQRT(MCM!M23^2+KK!M23^2) -> 4.1251218e-18 | P9: 45736 | Q9: =MCM!B23-NN!B23 -> -3.4e-19 | R9: =MCM!C23-NN!C23 -> -2.28967e-19 | S9: =MCM!D23-NN!D23 -> -3.7e-19 | T9: =MCM!E23-NN!E23 -> -1.92e-19 | U9: =MCM!F23-NN!F23 -> 1.11e-19 | V9: =MCM!G23-NN!G23 -> -8.69e-19 | W9: =MCM!H23-NN!H23 -> 1.57e-19 | X9: =MCM!I23-NN!I23 -> -7.66e-19 | ... AB9: =MCM!M23-NN!M23 -> -6.65e-19
A10: 45737 | B10: =MCM!B24-KK!B24 -> -5.8991855e-19 | C10: =SQRT(MCM!C24^2+KK!C24^2) -> 1.4844309e-18 | D10: =MCM!D24-KK!D24 -> -1.2599078e-18 | E10: =SQRT(MCM!E24^2+KK!E24^2) -> 1.6871378e-18 | F10: =MCM!F24-KK!F24 -> -4.0614484e-19 | G10: =SQRT(MCM!G24^2+KK!G24^2) -> 5.3683902e-18 | H10: =MCM!H24-KK!H24 -> -8.11026e-20 | I10: =SQRT(MCM!I24^2+KK!I24^2) -> 5.7332981e-18 | J10: =MCM!J24-KK!J24 -> -1.9175784e-18 | K10: =SQRT(MCM!K24^2+KK!K24^2) -> 4.630232e-18 | L10: =MCM!L24-KK!L24 -> -2.5366868e-18 | M10: =SQRT(MCM!M24^2+KK!M24^2) -> 4.9494788e-18 | N10: avg(abs(diff in w. means)) | P10: 45737 | Q10: =MCM!B24-NN!B24 -> -6.2e-19 | R10: =MCM!C24-NN!C24 -> -1.80975e-19 | S10: =MCM!D24-NN!D24 -> -7.2e-19 | T10: =MCM!E24-NN!E24 -> -3.2e-19 | U10: =MCM!F24-NN!F24 -> -4.1e-19 | V10: =MCM!G24-NN!G24 -> -1.38e-19 | W10: =MCM!H24-NN!H24 -> -1.52e-20 | X10: =MCM!I24-NN!I24 -> 2.46e-19 | ... AB10: =MCM!M24-NN!M24 -> -1.01e-18 | AC10: avg(abs(diff in w. means))
A11: Diff in weighted means | B11: =SUMPRODUCT(MCM!B16:B24,1/MCM!C16:C24^2)/SUM(1/MCM!C16:C24^2)-SUMPRODUCT(KK!B16:B24,1/KK!C16:C24^2)/SUM(1/KK!C16:C24^2) -> #VALUE! | D11: =SUMPRODUCT(MCM!D16:D24,1/MCM!E16:E24^2)/SUM(1/MCM!E16:E24^2)-SUMPRODUCT(KK!D16:D24,1/KK!E16:E24^2)/SUM(1/KK!E16:E24^2) -> #VALUE! | F11: =SUMPRODUCT(MCM!F16:F24,1/MCM!G16:G24^2)/SUM(1/MCM!G16:G24^2)-SUMPRODUCT(KK!F16:F24,1/KK!G16:G24^2)/SUM(1/KK!G16:G24^2) -> #VALUE! | H11: =SUMPRODUCT(MCM!H16:H24,1/MCM!I16:I24^2)/SUM(1/MCM!I16:I24^2)-SUMPRODUCT(KK!H16:H24,1/KK!I16:I24^2)/SUM(1/KK!I16:I24^2) -> #VALUE! | J11: =SUMPRODUCT(MCM!J16:J24,1/MCM!K16:K24^2)/SUM(1/MCM!K16:K24^2)-SUMPRODUCT(KK!J16:J24,1/KK!K16:K24^2)/SUM(1/KK!K16:K24^2) -> #VALUE! | L11: =SUMPRODUCT(MCM!L16:L24,1/MCM!M16:M24^2)/SUM(1/MCM!M16:M24^2)-SUMPRODUCT(KK!L16:L24,1/KK!M16:M24^2)/SUM(1/KK!M16:M24^2) -> #VALUE! | N11: =AVERAGE(ABS(B11),ABS(D11),ABS(F11),ABS(H11),ABS(J11),ABS(L11)) -> #VALUE! | P11: Diff in weighted means | Q11: =SUMPRODUCT(MCM!B16:B24,1/MCM!C16:C24^2)/SUM(1/MCM!C16:C24^2)-SUMPRODUCT(NN!B16:B24,1/NN!C16:C24^2)/SUM(1/NN!C16:C24^2) -> #VALUE! | S11: =SUMPRODUCT(MCM!D16:D24,1/MCM!E16:E24^2)/SUM(1/MCM!E16:E24^2)-SUMPRODUCT(NN!D16:D24,1/NN!E16:E24^2)/SUM(1/NN!E16:E24^2) -> #VALUE! | U11: =SUMPRODUCT(MCM!F16:F24,1/MCM!G16:G24^2)/SUM(1/MCM!G16:G24^2)-SUMPRODUCT(NN!F16:F24,1/NN!G16:G24^2)/SUM(1/NN!G16:G24^2) -> #VALUE! | W11: =SUMPRODUCT(MCM!H16:H24,1/MCM!I16:I24^2)/SUM(1/MCM!I16:I24^2)-SUMPRODUCT(NN!H16:H24,1/NN!I16:I24^2)/SUM(1/NN!I16:I24^2) -> #VALUE! | Y11: =SUMPRODUCT(MCM!J16:J24,1/MCM!K16:K24^2)/SUM(1/MCM!K16:K24^2)-SUMPRODUCT(NN!J16:J24,1/NN!K16:K24^2)/SUM(1/NN!K16:K24^2) -> #VALUE! | AA11: =SUMPRODUCT(MCM!L16:L24,1/MCM!M16:M24^2)/SUM(1/MCM!M16:M24^2)-SUMPRODUCT(NN!L16:L24,1/NN!M16:M24^2)/SUM(1/NN!M16:M24^2) -> #VALUE! | AC11: =AVERAGE(ABS(Q11),ABS(S11),ABS(U11),ABS(W11),ABS(Y11),ABS(AA11)) -> #VALUE!
A15: date | B15: Yb/Sr_ErYb_mean | C15: Yb/Sr_ErYb_err | D15: Yb/Sr_TiSa_mean | E15: Yb/Sr_TiSa_err | F15: Al/Yb_ErYb_mean | G15: Al/Yb_ErYb_err | H15: Al/Yb_TiSa_mean | I15: Al/Yb_TiSa_err | J15: Al/Sr_ErYb_mean | K15: Al/Sr_ErYb_err | L15: Al/Sr_TiSa_mean | M15: Al/Sr_TiSa_err | N15: KK - NN | P15: date | Q15: Yb/Sr_ErYb_mean | R15: Yb/Sr_ErYb_err | S15: Yb/Sr_TiSa_mean | T15: Yb/Sr_TiSa_err | U15: Al/Yb_ErYb_mean | V15: Al/Yb_ErYb_err | W15: Al/Yb_TiSa_mean | X15: Al/Yb_TiSa_err | Y15: Al/Sr_ErYb_mean | Z15: Al/Sr_ErYb_err | AA15: Al/Sr_TiSa_mean | AB15: Al/Sr_TiSa_err | AC15: MCM-JS
A16: 45715 | B16: =KK!B16-NN!B16 -> -2.0893403e-19 | C16: =SQRT(KK!C16^2+NN!C16^2) -> 1.6781406e-18 | D16: =KK!D16-NN!D16 -> -2.4802086e-21 | E16: =SQRT(KK!E16^2+NN!E16^2) -> 1.7056908e-18 | F16: =KK!F16-NN!F16 -> -1.1740705e-19 | G16: =SQRT(KK!G16^2+NN!G16^2) -> 4.4586469e-18 | H16: =KK!H16-NN!H16 -> -1.9777585e-19 | I16: =SQRT(KK!I16^2+NN!I16^2) -> 4.731677e-18 | J16: =KK!J16-NN!J16 -> -3.3992214e-19 | K16: =SQRT(KK!K16^2+NN!K16^2) -> 4.636615e-18 | L16: =KK!L16-NN!L16 -> -8.1352434e-20 | M16: =SQRT(KK!M16^2+NN!M16^2) -> 4.9270289e-18 | P16: 45715 | Q16: =MCM!B16-'JS YbReRunShifts'!B6 -> -6.5996705e-19 | R16: =MCM!C16-'JS YbReRunShifts'!C6 -> -3.071e-19 | S16: =MCM!D16-'JS YbReRunShifts'!D6 -> -1.0036877e-18 | T16: =MCM!E16-'JS YbReRunShifts'!E6 -> -3.1e-19 | U16: =MCM!F16-'JS YbReRunShifts'!F6 -> -5.1455369e-19 | V16: =MCM!G16-'JS YbReRunShifts'!G6 -> -1.396e-18 | W16: =MCM!H16-'JS YbReRunShifts'!H6 -> -6.1270978e-19 | X16: =MCM!I16-'JS YbReRunShifts'!I6 -> -1.543e-18 | ... AB16: =MCM!M16-'JS YbReRunShifts'!M6 -> -1.186e-18
A17: 45716 | B17: =KK!B17-NN!B17 -> -1.1183164e-19 | C17: =SQRT(KK!C17^2+NN!C17^2) -> 1.6017873e-18 | D17: =KK!D17-NN!D17 -> 4.9810914e-19 | E17: =SQRT(KK!E17^2+NN!E17^2) -> 1.5619272e-18 | F17: =KK!F17-NN!F17 -> -5.7232881e-20 | G17: =SQRT(KK!G17^2+NN!G17^2) -> 4.9732403e-18 | H17: =KK!H17-NN!H17 -> -1.4698386e-19 | I17: =SQRT(KK!I17^2+NN!I17^2) -> 4.9719127e-18 | J17: =KK!J17-NN!J17 -> -6.2166991e-20 | K17: =SQRT(KK!K17^2+NN!K17^2) -> 4.058031e-18 | L17: =KK!L17-NN!L17 -> 8.0769009e-19 | M17: =SQRT(KK!M17^2+NN!M17^2) -> 4.0759758e-18 | P17: 45716 | Q17: =MCM!B17-'JS YbReRunShifts'!B7 -> -5.6549411e-19 | R17: =MCM!C17-'JS YbReRunShifts'!C7 -> -2.426e-19 | S17: =MCM!D17-'JS YbReRunShifts'!D7 -> -1.2821092e-18 | T17: =MCM!E17-'JS YbReRunShifts'!E7 -> -2.6e-19 | U17: =MCM!F17-'JS YbReRunShifts'!F7 -> -5.194479e-19 | V17: =MCM!G17-'JS YbReRunShifts'!G7 -> -1.326e-18 | W17: =MCM!H17-'JS YbReRunShifts'!H7 -> -6.0830157e-19 | X17: =MCM!I17-'JS YbReRunShifts'!I7 -> -1.378e-18 | ... AB17: =MCM!M17-'JS YbReRunShifts'!M7 -> -1.288e-18
A18: 45720 | B18: =KK!B18-NN!B18 -> -5.9799494e-20 | C18: =SQRT(KK!C18^2+NN!C18^2) -> 1.4815517e-18 | D18: =KK!D18-NN!D18 -> 2.7185634e-19 | E18: =SQRT(KK!E18^2+NN!E18^2) -> 1.4812973e-18 | F18: =KK!F18-NN!F18 -> 2.7249628e-20 | G18: =SQRT(KK!G18^2+NN!G18^2) -> 5.6636573e-18 | H18: =KK!H18-NN!H18 -> -5.6852026e-20 | I18: =SQRT(KK!I18^2+NN!I18^2) -> 5.6862074e-18 | J18: =KK!J18-NN!J18 -> -3.6985806e-20 | K18: =SQRT(KK!K18^2+NN!K18^2) -> 5.6802054e-18 | L18: =KK!L18-NN!L18 -> 8.8010379e-20 | M18: =SQRT(KK!M18^2+NN!M18^2) -> 5.6988652e-18 | P18: 45720 | Q18: =MCM!B18-'JS YbReRunShifts'!B8 -> -7.058907e-19 | R18: =MCM!C18-'JS YbReRunShifts'!C8 -> -1.442e-19 | S18: =MCM!D18-'JS YbReRunShifts'!D8 -> -8.7679565e-19 | T18: =MCM!E18-'JS YbReRunShifts'!E8 -> -1.49e-19 | U18: =MCM!F18-'JS YbReRunShifts'!F8 -> -2.8942569e-19 | V18: =MCM!G18-'JS YbReRunShifts'!G8 -> -1.664e-18 | W18: =MCM!H18-'JS YbReRunShifts'!H8 -> -3.7861682e-19 | X18: =MCM!I18-'JS YbReRunShifts'!I8 -> -1.658e-18 | ... AB18: =MCM!M18-'JS YbReRunShifts'!M8 -> -1.695e-18
A19: 45722 | B19: =KK!B19-NN!B19 -> -1.8415806e-20 | C19: =SQRT(KK!C19^2+NN!C19^2) -> 1.8347551e-18 | D19: =KK!D19-NN!D19 -> 8.287047e-19 | E19: =SQRT(KK!E19^2+NN!E19^2) -> 1.8461638e-18 | F19: =KK!F19-NN!F19 -> -1.024099e-18 | G19: =SQRT(KK!G19^2+NN!G19^2) -> 6.0543188e-18 | H19: =KK!H19-NN!H19 -> -9.9851844e-19 | I19: =SQRT(KK!I19^2+NN!I19^2) -> 6.0548101e-18 | J19: =KK!J19-NN!J19 -> 1.0014e-18 | K19: =SQRT(KK!K19^2+NN!K19^2) -> 6.2797088e-18 | L19: =KK!L19-NN!L19 -> 1.6920346e-18 | M19: =SQRT(KK!M19^2+NN!M19^2) -> 6.2603289e-18 | P19: 45722 | Q19: =MCM!B19-'JS YbReRunShifts'!B9 -> -8.0153751e-19 | R19: =MCM!C19-'JS YbReRunShifts'!C9 -> -9.465e-19 | S19: =MCM!D19-'JS YbReRunShifts'!D9 -> -1.6617594e-18 | T19: =MCM!E19-'JS YbReRunShifts'!E9 -> -9.23e-19 | U19: =MCM!F19-'JS YbReRunShifts'!F9 -> -3.0992583e-19 | V19: =MCM!G19-'JS YbReRunShifts'!G9 -> -1.546e-18 | W19: =MCM!H19-'JS YbReRunShifts'!H9 -> -3.9657839e-19 | X19: =MCM!I19-'JS YbReRunShifts'!I9 -> -1.566e-18 | ... AB19: =MCM!M19-'JS YbReRunShifts'!M9 -> -1.625e-18
A20: 45723 | B20: =KK!B20-NN!B20 -> -1.084046e-19 | C20: =SQRT(KK!C20^2+NN!C20^2) -> 2.1464824e-18 | D20: =KK!D20-NN!D20 -> 9.3836827e-20 | E20: =SQRT(KK!E20^2+NN!E20^2) -> 2.1603166e-18 | F20: =KK!F20-NN!F20 -> 9.4745416e-20 | G20: =SQRT(KK!G20^2+NN!G20^2) -> 6.349486e-18 | H20: =KK!H20-NN!H20 -> 2.8879377e-20 | I20: =SQRT(KK!I20^2+NN!I20^2) -> 6.2860134e-18 | J20: =KK!J20-NN!J20 -> -9.0188926e-19 | K20: =SQRT(KK!K20^2+NN!K20^2) -> 4.5415724e-18 | L20: =KK!L20-NN!L20 -> -4.4143542e-19 | M20: =SQRT(KK!M20^2+NN!M20^2) -> 4.467794e-18 | P20: 45723 | Q20: =MCM!B20-'JS YbReRunShifts'!B10 -> -6.9327727e-19 | R20: =MCM!C20-'JS YbReRunShifts'!C10 -> -2.13e-19 | S20: =MCM!D20-'JS YbReRunShifts'!D10 -> -7.6561566e-19 | T20: =MCM!E20-'JS YbReRunShifts'!E10 -> -2.07e-19 | U20: =MCM!F20-'JS YbReRunShifts'!F10 -> -4.0757439e-19 | V20: =MCM!G20-'JS YbReRunShifts'!G10 -> -1.733e-18 | W20: =MCM!H20-'JS YbReRunShifts'!H10 -> -4.8677833e-19 | X20: =MCM!I20-'JS YbReRunShifts'!I10 -> -1.599e-18 | ... AB20: =MCM!M20-'JS YbReRunShifts'!M10 -> -1.194e-18
A21: 45729 | B21: =KK!B21-NN!B21 -> -2.0568663e-20 | C21: =SQRT(KK!C21^2+NN!C21^2) -> 1.5943587e-18 | D21: =KK!D21-NN!D21 -> 4.2540578e-20 | E21: =SQRT(KK!E21^2+NN!E21^2) -> 1.6228134e-18 | F21: =KK!F21-NN!F21 -> 7.7299537e-20 | G21: =SQRT(KK!G21^2+NN!G21^2) -> 5.3349287e-18 | H21: =KK!H21-NN!H21 -> -3.0537296e-20 | I21: =SQRT(KK!I21^2+NN!I21^2) -> 5.2883914e-18 | J21: =KK!J21-NN!J21 -> 1.5087422e-18 | K21: =SQRT(KK!K21^2+NN!K21^2) -> 4.8786356e-18 | L21: =KK!L21-NN!L21 -> 1.5464414e-18 | M21: =SQRT(KK!M21^2+NN!M21^2) -> 4.8467904e-18 | P21: 45729 | Q21: =MCM!B21-'JS YbReRunShifts'!B11 -> -7.0427269e-19 | R21: =MCM!C21-'JS YbReRunShifts'!C11 -> -3.34602e-19 | S21: =MCM!D21-'JS YbReRunShifts'!D11 -> -8.5625808e-19 | T21: =MCM!E21-'JS YbReRunShifts'!E11 -> -3.41e-19 | U21: =MCM!F21-'JS YbReRunShifts'!F11 -> -2.2832328e-19 | V21: =MCM!G21-'JS YbReRunShifts'!G11 -> -1.704e-18 | W21: =MCM!H21-'JS YbReRunShifts'!H11 -> -2.9013288e-19 | X21: =MCM!I21-'JS YbReRunShifts'!I11 -> -1.689e-18 | ... AB21: =MCM!M21-'JS YbReRunShifts'!M11 -> -1.357e-18
A22: 45734 | B22: =KK!B22-NN!B22 -> -2.8321198e-19 | C22: =SQRT(KK!C22^2+NN!C22^2) -> 1.9118691e-18 | D22: =KK!D22-NN!D22 -> 3.5996901e-19 | E22: =SQRT(KK!E22^2+NN!E22^2) -> 1.9714721e-18 | F22: =KK!F22-NN!F22 -> 5.8580935e-20 | G22: =SQRT(KK!G22^2+NN!G22^2) -> 7.968812e-18 | H22: =KK!H22-NN!H22 -> 2.0785111e-20 | I22: =SQRT(KK!I22^2+NN!I22^2) -> 8.0573592e-18 | J22: =KK!J22-NN!J22 -> -1.8825151e-20 | K22: =SQRT(KK!K22^2+NN!K22^2) -> 1.0916293e-17 | L22: =KK!L22-NN!L22 -> 1.3458163e-19 | M22: =SQRT(KK!M22^2+NN!M22^2) -> 1.1055493e-17 | P22: 45734 | Q22: =MCM!B22-'JS YbReRunShifts'!B12 -> -4.0960754e-19 | R22: =MCM!C22-'JS YbReRunShifts'!C12 -> -1.37898e-18 | S22: =MCM!D22-'JS YbReRunShifts'!D12 -> -1.1941814e-18 | T22: =MCM!E22-'JS YbReRunShifts'!E12 -> -1.364e-18 | U22: =MCM!F22-'JS YbReRunShifts'!F12 -> -4.5409603e-19 | V22: =MCM!G22-'JS YbReRunShifts'!G12 -> -2.024e-18 | W22: =MCM!H22-'JS YbReRunShifts'!H12 -> -2.5535403e-19 | X22: =MCM!I22-'JS YbReRunShifts'!I12 -> -2.079e-18 | ... AB22: =MCM!M22-'JS YbReRunShifts'!M12 -> -2.301e-18
A23: 45736 | B23: =KK!B23-NN!B23 -> -1.6937067e-20 | C23: =SQRT(KK!C23^2+NN!C23^2) -> 1.4413758e-18 | D23: =KK!D23-NN!D23 -> 2.1192618e-19 | E23: =SQRT(KK!E23^2+NN!E23^2) -> 1.4661676e-18 | F23: =KK!F23-NN!F23 -> -3.4074887e-20 | G23: =SQRT(KK!G23^2+NN!G23^2) -> 4.7591808e-18 | H23: =KK!H23-NN!H23 -> -4.6393564e-20 | I23: =SQRT(KK!I23^2+NN!I23^2) -> 4.6592474e-18 | J23: =KK!J23-NN!J23 -> -6.5979392e-19 | K23: =SQRT(KK!K23^2+NN!K23^2) -> 4.623174e-18 | L23: =KK!L23-NN!L23 -> -7.4838492e-20 | M23: =SQRT(KK!M23^2+NN!M23^2) -> 4.5959771e-18 | P23: 45736 | Q23: =MCM!B23-'JS YbReRunShifts'!B13 -> -3.7275935e-19 | R23: =MCM!C23-'JS YbReRunShifts'!C13 -> -2.43967e-19 | S23: =MCM!D23-'JS YbReRunShifts'!D13 -> -5.7748056e-19 | T23: =MCM!E23-'JS YbReRunShifts'!E13 -> -2.82e-19 | U23: =MCM!F23-'JS YbReRunShifts'!F13 -> -2.8484953e-19 | V23: =MCM!G23-'JS YbReRunShifts'!G13 -> -1.439e-18 | W23: =MCM!H23-'JS YbReRunShifts'!H13 -> -3.7136346e-19 | X23: =MCM!I23-'JS YbReRunShifts'!I13 -> -1.416e-18 | ... AB23: =MCM!M23-'JS YbReRunShifts'!M13 -> -1.435e-18
A24: 45737 | B24: =KK!B24-NN!B24 -> -3.0081448e-20 | C24: =SQRT(KK!C24^2+NN!C24^2) -> 1.6117953e-18 | D24: =KK!D24-NN!D24 -> 5.3990779e-19 | E24: =SQRT(KK!E24^2+NN!E24^2) -> 1.9229233e-18 | F24: =KK!F24-NN!F24 -> -3.8551613e-21 | G24: =SQRT(KK!G24^2+NN!G24^2) -> 5.4669927e-18 | H24: =KK!H24-NN!H24 -> 6.59026e-20 | I24: =SQRT(KK!I24^2+NN!I24^2) -> 5.5610998e-18 | J24: =KK!J24-NN!J24 -> 7.3757836e-19 | K24: =SQRT(KK!K24^2+NN!K24^2) -> 5.3190022e-18 | L24: =KK!L24-NN!L24 -> 1.3666868e-18 | M24: =SQRT(KK!M24^2+NN!M24^2) -> 5.6085863e-18 | N24: avg(abs(diff in w. means)) | P24: 45737 | Q24: =MCM!B24-'JS YbReRunShifts'!B14 -> -5.9121157e-19 | R24: =MCM!C24-'JS YbReRunShifts'!C14 -> -4.00975e-19 | S24: =MCM!D24-'JS YbReRunShifts'!D14 -> -8.686233e-19 | T24: =MCM!E24-'JS YbReRunShifts'!E14 -> -3.8e-19 | U24: =MCM!F24-'JS YbReRunShifts'!F14 -> -3.0732758e-19 | V24: =MCM!G24-'JS YbReRunShifts'!G14 -> -1.298e-18 | W24: =MCM!H24-'JS YbReRunShifts'!H14 -> 8.0741526e-21 | X24: =MCM!I24-'JS YbReRunShifts'!I14 -> -1.224e-18 | ... AB24: =MCM!M24-'JS YbReRunShifts'!M14 -> -1.18e-18 | AC24: avg(abs(diff in w. means))
A25: Diff in weighted means | B25: =SUMPRODUCT(KK!B16:B24,1/KK!C16:C24^2)/SUM(1/KK!C16:C24^2)-SUMPRODUCT(NN!B16:B24,1/NN!C16:C24^2)/SUM(1/NN!C16:C24^2) -> #VALUE! | D25: =SUMPRODUCT(KK!D16:D24,1/KK!E16:E24^2)/SUM(1/KK!E16:E24^2)-SUMPRODUCT(NN!D16:D24,1/NN!E16:E24^2)/SUM(1/NN!E16:E24^2) -> #VALUE! | F25: =SUMPRODUCT(KK!F16:F24,1/KK!G16:G24^2)/SUM(1/KK!G16:G24^2)-SUMPRODUCT(NN!F16:F24,1/NN!G16:G24^2)/SUM(1/NN!G16:G24^2) -> #VALUE! | H25: =SUMPRODUCT(KK!H16:H24,1/KK!I16:I24^2)/SUM(1/KK!I16:I24^2)-SUMPRODUCT(NN!H16:H24,1/NN!I16:I24^2)/SUM(1/NN!I16:I24^2) -> #VALUE! | J25: =SUMPRODUCT(KK!J16:J24,1/KK!K16:K24^2)/SUM(1/KK!K16:K24^2)-SUMPRODUCT(NN!J16:J24,1/NN!K16:K24^2)/SUM(1/NN!K16:K24^2) -> #VALUE! | L25: =SUMPRODUCT(KK!L16:L24,1/KK!M16:M24^2)/SUM(1/KK!M16:M24^2)-SUMPRODUCT(NN!L16:L24,1/NN!M16:M24^2)/SUM(1/NN!M16:M24^2) -> #VALUE! | N25: =AVERAGE(ABS(B25),ABS(D25),ABS(F25),ABS(H25),ABS(J25),ABS(L25)) -> #VALUE! | P25: wm diff | Q25: =SUMPRODUCT(MCM!B16:B24,1/MCM!C16:C24^2)/SUM(1/MCM!C16:C24^2)-SUMPRODUCT('JS YbReRunShifts'!B6:B14,1/'JS YbReRunShifts'!C6:C14^2)/SUM(1/'JS YbReRunShifts'!C6:C14^2) -> #VALUE! | S25: =SUMPRODUCT(MCM!D16:D24,1/MCM!E16:E24^2)/SUM(1/MCM!E16:E24^2)-SUMPRODUCT('JS YbReRunShifts'!D6:D14,1/'JS YbReRunShifts'!E6:E14^2)/SUM(1/'JS YbReRunShifts'!E6:E14^2) -> #VALUE! | U25: =SUMPRODUCT(MCM!F16:F24,1/MCM!G16:G24^2)/SUM(1/MCM!G16:G24^2)-SUMPRODUCT('JS YbReRunShifts'!F6:F14,1/'JS YbReRunShifts'!G6:G14^2)/SUM(1/'JS YbReRunShifts'!G6:G14^2) -> #VALUE! | W25: =SUMPRODUCT(MCM!H16:H24,1/MCM!I16:I24^2)/SUM(1/MCM!I16:I24^2)-SUMPRODUCT('JS YbReRunShifts'!H6:H14,1/'JS YbReRunShifts'!I6:I14^2)/SUM(1/'JS YbReRunShifts'!I6:I14^2) -> #VALUE! | Y25: =SUMPRODUCT(MCM!J16:J24,1/MCM!K16:K24^2)/SUM(1/MCM!K16:K24^2)-SUMPRODUCT('JS YbReRunShifts'!J6:J14,1/'JS YbReRunShifts'!K6:K14^2)/SUM(1/'JS YbReRunShifts'!K6:K14^2) -> #VALUE! | AA25: =SUMPRODUCT(MCM!L16:L24,1/MCM!M16:M24^2)/SUM(1/MCM!M16:M24^2)-SUMPRODUCT('JS YbReRunShifts'!L6:L14,1/'JS YbReRunShifts'!M6:M14^2)/SUM(1/'JS YbReRunShifts'!M6:M14^2) -> #VALUE! | AC25: =AVERAGE(ABS(Q25),ABS(S25),ABS(U25),ABS(W25),ABS(Y25),ABS(AA25)) -> #VALUE!
A29: date | B29: Yb/Sr_ErYb_mean | C29: Yb/Sr_ErYb_err | D29: Yb/Sr_TiSa_mean | E29: Yb/Sr_TiSa_err | F29: Al/Yb_ErYb_mean | G29: Al/Yb_ErYb_err | H29: Al/Yb_TiSa_mean | I29: Al/Yb_TiSa_err | J29: Al/Sr_ErYb_mean | K29: Al/Sr_ErYb_err | L29: Al/Sr_TiSa_mean | M29: Al/Sr_TiSa_err | N29: KK-JS | P29: date | Q29: Yb/Sr_ErYb_mean | R29: Yb/Sr_ErYb_err | S29: Yb/Sr_TiSa_mean | T29: Yb/Sr_TiSa_err | U29: Al/Yb_ErYb_mean | V29: Al/Yb_ErYb_err | W29: Al/Yb_TiSa_mean | X29: Al/Yb_TiSa_err | Y29: Al/Sr_ErYb_mean | Z29: Al/Sr_ErYb_err | AA29: Al/Sr_TiSa_mean | AB29: Al/Sr_TiSa_err | AC29: NN-JS
A30: 45715 | B30: =KK!B16-'JS YbReRunShifts'!B6 -> -2.4890108e-19 | C30: =KK!C16-'JS YbReRunShifts'!C6 -> -3.1116445e-19 | D30: =KK!D16-'JS YbReRunShifts'!D6 -> -3.8616786e-19 | E30: =KK!E16-'JS YbReRunShifts'!E6 -> -2.5574405e-19 | F30: =KK!F16-'JS YbReRunShifts'!F6 -> -8.9607452e-21 | G30: =KK!G16-'JS YbReRunShifts'!G6 -> -1.3506452e-18 | H30: =KK!H16-'JS YbReRunShifts'!H6 -> -1.8048563e-19 | I30: =KK!I16-'JS YbReRunShifts'!I6 -> -1.4540107e-18 | ... M30: =KK!M16-'JS YbReRunShifts'!M6 -> -1.066865e-18 | P30: 45715 | Q30: =NN!B16-'JS YbReRunShifts'!B6 -> -3.996705e-20 | R30: =NN!C16-'JS YbReRunShifts'!C6 -> -5e-20 | S30: =NN!D16-'JS YbReRunShifts'!D6 -> -3.8368765e-19 | T30: =NN!E16-'JS YbReRunShifts'!E6 -> -6e-20 | U30: =NN!F16-'JS YbReRunShifts'!F6 -> 1.0844631e-19 | V30: =NN!G16-'JS YbReRunShifts'!G6 -> -9e-19 | W30: =NN!H16-'JS YbReRunShifts'!H6 -> 1.729022e-20 | X30: =NN!I16-'JS YbReRunShifts'!I6 -> -1.18e-18 | ... AB30: =NN!M16-'JS YbReRunShifts'!M6 -> -8.1e-19
A31: 45716 | B31: =KK!B17-'JS YbReRunShifts'!B7 -> -1.3732574e-19 | C31: =KK!C17-'JS YbReRunShifts'!C7 -> -2.1500114e-19 | D31: =KK!D17-'JS YbReRunShifts'!D7 -> -2.4400008e-19 | E31: =KK!E17-'JS YbReRunShifts'!E7 -> -2.4132345e-19 | F31: =KK!F17-'JS YbReRunShifts'!F7 -> 5.6319218e-20 | G31: =KK!G17-'JS YbReRunShifts'!G7 -> -1.2081709e-18 | H31: =KK!H17-'JS YbReRunShifts'!H7 -> -1.2028543e-19 | I31: =KK!I17-'JS YbReRunShifts'!I7 -> -1.1985472e-18 | ... M31: =KK!M17-'JS YbReRunShifts'!M7 -> -1.1857212e-18 | P31: 45716 | Q31: =NN!B17-'JS YbReRunShifts'!B7 -> -2.5494107e-20 | R31: =NN!C17-'JS YbReRunShifts'!C7 -> -1.8e-19 | S31: =NN!D17-'JS YbReRunShifts'!D7 -> -7.4210922e-19 | T31: =NN!E17-'JS YbReRunShifts'!E7 -> -2.1e-19 | U31: =NN!F17-'JS YbReRunShifts'!F7 -> 1.135521e-19 | V31: =NN!G17-'JS YbReRunShifts'!G7 -> -6.6e-19 | W31: =NN!H17-'JS YbReRunShifts'!H7 -> 2.6698429e-20 | X31: =NN!I17-'JS YbReRunShifts'!I7 -> -6.7e-19 | ... AB31: =NN!M17-'JS YbReRunShifts'!M7 -> -1.17e-18
A32: 45720 | B32: =KK!B18-'JS YbReRunShifts'!B8 -> -7.569019e-20 | C32: =KK!C18-'JS YbReRunShifts'!C8 -> -1.9525838e-19 | D32: =KK!D18-'JS YbReRunShifts'!D8 -> 9.5060691e-20 | E32: =KK!E18-'JS YbReRunShifts'!E8 -> -2.056262e-19 | F32: =KK!F18-'JS YbReRunShifts'!F8 -> 1.3582394e-19 | G32: =KK!G18-'JS YbReRunShifts'!G8 -> -1.4764035e-18 | H32: =KK!H18-'JS YbReRunShifts'!H8 -> -3.646885e-20 | I32: =KK!I18-'JS YbReRunShifts'!I8 -> -1.4936549e-18 | ... M32: =KK!M18-'JS YbReRunShifts'!M8 -> -1.4833482e-18 | P32: 45720 | Q32: =NN!B18-'JS YbReRunShifts'!B8 -> -1.5890696e-20 | R32: =NN!C18-'JS YbReRunShifts'!C8 -> -1.5e-19 | S32: =NN!D18-'JS YbReRunShifts'!D8 -> -1.7679565e-19 | T32: =NN!E18-'JS YbReRunShifts'!E8 -> -1.6e-19 | U32: =NN!F18-'JS YbReRunShifts'!F8 -> 1.0857431e-19 | V32: =NN!G18-'JS YbReRunShifts'!G8 -> -9.7e-19 | W32: =NN!H18-'JS YbReRunShifts'!H8 -> 2.0383176e-20 | X32: =NN!I18-'JS YbReRunShifts'!I8 -> -1e-18 | ... AB32: =NN!M18-'JS YbReRunShifts'!M8 -> -1.03e-18
A33: 45722 | B33: =KK!B19-'JS YbReRunShifts'!B9 -> -4.9953315e-20 | C33: =KK!C19-'JS YbReRunShifts'!C9 -> -1.0684456e-18 | D33: =KK!D19-'JS YbReRunShifts'!D9 -> -4.3054721e-20 | E33: =KK!E19-'JS YbReRunShifts'!E9 -> -1.0515127e-18 | F33: =KK!F19-'JS YbReRunShifts'!F9 -> -1.2024873e-20 | G33: =KK!G19-'JS YbReRunShifts'!G9 -> -1.5583808e-18 | H33: =KK!H19-'JS YbReRunShifts'!H9 -> -1.5109683e-19 | I33: =KK!I19-'JS YbReRunShifts'!I9 -> -1.5675963e-18 | ... M33: =KK!M19-'JS YbReRunShifts'!M9 -> -1.2607294e-18 | P33: 45722 | Q33: =NN!B19-'JS YbReRunShifts'!B9 -> -3.1537509e-20 | R33: =NN!C19-'JS YbReRunShifts'!C9 -> -9.4e-19 | S33: =NN!D19-'JS YbReRunShifts'!D9 -> -8.7175942e-19 | T33: =NN!E19-'JS YbReRunShifts'!E9 -> -9.4e-19 | U33: =NN!F19-'JS YbReRunShifts'!F9 -> 1.0120742e-18 | V33: =NN!G19-'JS YbReRunShifts'!G9 -> -6.3e-19 | W33: =NN!H19-'JS YbReRunShifts'!H9 -> 8.4742161e-19 | X33: =NN!I19-'JS YbReRunShifts'!I9 -> -6.4e-19 | ... AB33: =NN!M19-'JS YbReRunShifts'!M9 -> -7.6e-19
A34: 45723 | B34: =KK!B20-'JS YbReRunShifts'!B10 -> -1.5168187e-19 | C34: =KK!C20-'JS YbReRunShifts'!C10 -> -1.8802675e-19 | D34: =KK!D20-'JS YbReRunShifts'!D10 -> 4.8221164e-20 | E34: =KK!E20-'JS YbReRunShifts'!E10 -> -1.6671537e-19 | F34: =KK!F20-'JS YbReRunShifts'!F10 -> 2.0417102e-19 | G34: =KK!G20-'JS YbReRunShifts'!G10 -> -1.9005775e-18 | H34: =KK!H20-'JS YbReRunShifts'!H10 -> 5.6101046e-20 | I34: =KK!I20-'JS YbReRunShifts'!I10 -> -1.8245652e-18 | ... M34: =KK!M20-'JS YbReRunShifts'!M10 -> -1.333292e-18 | P34: 45723 | Q34: =NN!B20-'JS YbReRunShifts'!B10 -> -4.3277266e-20 | R34: =NN!C20-'JS YbReRunShifts'!C10 -> -4e-20 | S34: =NN!D20-'JS YbReRunShifts'!D10 -> -4.5615663e-20 | T34: =NN!E20-'JS YbReRunShifts'!E10 -> -6e-20 | U34: =NN!F20-'JS YbReRunShifts'!F10 -> 1.0942561e-19 | V34: =NN!G20-'JS YbReRunShifts'!G10 -> -1.3e-18 | W34: =NN!H20-'JS YbReRunShifts'!H10 -> 2.7221669e-20 | X34: =NN!I20-'JS YbReRunShifts'!I10 -> -1.32e-18 | ... AB34: =NN!M20-'JS YbReRunShifts'!M10 -> -8.1e-19
A35: 45729 | B35: =KK!B21-'JS YbReRunShifts'!B11 -> -4.5684135e-19 | C35: =KK!C21-'JS YbReRunShifts'!C11 -> -2.6569942e-19 | D35: =KK!D21-'JS YbReRunShifts'!D11 -> -4.937175e-19 | E35: =KK!E21-'JS YbReRunShifts'!E11 -> -2.554453e-19 | F35: =KK!F21-'JS YbReRunShifts'!F11 -> 1.5997626e-19 | G35: =KK!G21-'JS YbReRunShifts'!G11 -> -1.4854754e-18 | H35: =KK!H21-'JS YbReRunShifts'!H11 -> -2.2670172e-20 | I35: =KK!I21-'JS YbReRunShifts'!I11 -> -1.4613367e-18 | ... M35: =KK!M21-'JS YbReRunShifts'!M11 -> -9.871166e-19 | P35: 45729 | Q35: =NN!B21-'JS YbReRunShifts'!B11 -> -4.3627269e-19 | R35: =NN!C21-'JS YbReRunShifts'!C11 -> -2.2e-19 | S35: =NN!D21-'JS YbReRunShifts'!D11 -> -5.3625808e-19 | T35: =NN!E21-'JS YbReRunShifts'!E11 -> -2.1e-19 | U35: =NN!F21-'JS YbReRunShifts'!F11 -> 8.2676718e-20 | V35: =NN!G21-'JS YbReRunShifts'!G11 -> -1.43e-18 | W35: =NN!H21-'JS YbReRunShifts'!H11 -> 7.8671247e-21 | X35: =NN!I21-'JS YbReRunShifts'!I11 -> -1.4e-18 | ... AB35: =NN!M21-'JS YbReRunShifts'!M11 -> -5.9e-19
A36: 45734 | B36: =KK!B22-'JS YbReRunShifts'!B12 -> -2.5281952e-19 | C36: =KK!C22-'JS YbReRunShifts'!C12 -> -1.4775666e-18 | D36: =KK!D22-'JS YbReRunShifts'!D12 -> -4.1421236e-19 | E36: =KK!E22-'JS YbReRunShifts'!E12 -> -1.4206633e-18 | F36: =KK!F22-'JS YbReRunShifts'!F12 -> -4.515092e-21 | G36: =KK!G22-'JS YbReRunShifts'!G12 -> -2.2820342e-18 | H36: =KK!H22-'JS YbReRunShifts'!H12 -> 1.5743108e-19 | I36: =KK!I22-'JS YbReRunShifts'!I12 -> -2.3274435e-18 | ... M36: =KK!M22-'JS YbReRunShifts'!M12 -> -2.6322376e-18 | P36: 45734 | Q36: =NN!B22-'JS YbReRunShifts'!B12 -> 3.0392461e-20 | R36: =NN!C22-'JS YbReRunShifts'!C12 -> -1.23e-18 | S36: =NN!D22-'JS YbReRunShifts'!D12 -> -7.7418137e-19 | T36: =NN!E22-'JS YbReRunShifts'!E12 -> -1.2e-18 | U36: =NN!F22-'JS YbReRunShifts'!F12 -> -6.3096027e-20 | V36: =NN!G22-'JS YbReRunShifts'!G12 -> -2.09e-18 | W36: =NN!H22-'JS YbReRunShifts'!H12 -> 1.3664597e-19 | X36: =NN!I22-'JS YbReRunShifts'!I12 -> -2.1e-18 | ... AB36: =NN!M22-'JS YbReRunShifts'!M12 -> -1.42e-18
A37: 45736 | B37: =KK!B23-'JS YbReRunShifts'!B13 -> -4.9696417e-20 | C37: =KK!C23-'JS YbReRunShifts'!C13 -> -1.8356867e-19 | D37: =KK!D23-'JS YbReRunShifts'!D13 -> 4.4456163e-21 | E37: =KK!E23-'JS YbReRunShifts'!E13 -> -2.4211301e-19 | F37: =KK!F23-'JS YbReRunShifts'!F13 -> -4.2992441e-19 | G37: =KK!G23-'JS YbReRunShifts'!G13 -> -1.187928e-18 | H37: =KK!H23-'JS YbReRunShifts'!H13 -> -5.7475702e-19 | I37: =KK!I23-'JS YbReRunShifts'!I13 -> -1.1606458e-18 | ... M37: =KK!M23-'JS YbReRunShifts'!M13 -> -1.1197223e-18 | P37: 45736 | Q37: =NN!B23-'JS YbReRunShifts'!B13 -> -3.2759349e-20 | R37: =NN!C23-'JS YbReRunShifts'!C13 -> -1.5e-20 | S37: =NN!D23-'JS YbReRunShifts'!D13 -> -2.0748056e-19 | T37: =NN!E23-'JS YbReRunShifts'!E13 -> -9e-20 | U37: =NN!F23-'JS YbReRunShifts'!F13 -> -3.9584953e-19 | V37: =NN!G23-'JS YbReRunShifts'!G13 -> -5.7e-19 | W37: =NN!H23-'JS YbReRunShifts'!H13 -> -5.2836346e-19 | X37: =NN!I23-'JS YbReRunShifts'!I13 -> -6.5e-19 | ... AB37: =NN!M23-'JS YbReRunShifts'!M13 -> -7.7e-19
A38: 45737 | B38: =KK!B24-'JS YbReRunShifts'!B14 -> -1.293015e-21 | C38: =KK!C24-'JS YbReRunShifts'!C14 -> -3.0205456e-19 | D38: =KK!D24-'JS YbReRunShifts'!D14 -> 3.912845e-19 | E38: =KK!E24-'JS YbReRunShifts'!E14 -> -3.3446145e-19 | F38: =KK!F24-'JS YbReRunShifts'!F14 -> 9.8817262e-20 | G38: =KK!G24-'JS YbReRunShifts'!G14 -> -1.3099593e-18 | H38: =KK!H24-'JS YbReRunShifts'!H14 -> 8.9176752e-20 | I38: =KK!I24-'JS YbReRunShifts'!I14 -> -1.2680115e-18 | ... M38: =KK!M24-'JS YbReRunShifts'!M14 -> -1.3832447e-19 | N38: avg(abs(diff in w. means)) | P38: 45737 | Q38: =NN!B24-'JS YbReRunShifts'!B14 -> 2.8788433e-20 | R38: =NN!C24-'JS YbReRunShifts'!C14 -> -2.2e-19 | S38: =NN!D24-'JS YbReRunShifts'!D14 -> -1.486233e-19 | T38: =NN!E24-'JS YbReRunShifts'!E14 -> -6e-20 | U38: =NN!F24-'JS YbReRunShifts'!F14 -> 1.0267242e-19 | V38: =NN!G24-'JS YbReRunShifts'!G14 -> -1.16e-18 | W38: =NN!H24-'JS YbReRunShifts'!H14 -> 2.3274153e-20 | X38: =NN!I24-'JS YbReRunShifts'!I14 -> -1.47e-18 | ... AB38: =NN!M24-'JS YbReRunShifts'!M14 -> -1.7e-19 | AC38: avg(abs(diff in w. means))
A39: wm diff | B39: =SUMPRODUCT(KK!B16:B24,1/KK!C16:C24^2)/SUM(1/KK!C16:C24^2)-SUMPRODUCT('JS YbReRunShifts'!B6:B14,1/'JS YbReRunShifts'!C6:C14^2)/SUM(1/'JS YbReRunShifts'!C6:C14^2) -> #VALUE! | D39: =SUMPRODUCT(KK!D16:D24,1/KK!E16:E24^2)/SUM(1/KK!E16:E24^2)-SUMPRODUCT('JS YbReRunShifts'!D6:D14,1/'JS YbReRunShifts'!E6:E14^2)/SUM(1/'JS YbReRunShifts'!E6:E14^2) -> #VALUE! | F39: =SUMPRODUCT(KK!F16:F24,1/KK!G16:G24^2)/SUM(1/KK!G16:G24^2)-SUMPRODUCT('JS YbReRunShifts'!F6:F14,1/'JS YbReRunShifts'!G6:G14^2)/SUM(1/'JS YbReRunShifts'!G6:G14^2) -> #VALUE! | H39: =SUMPRODUCT(KK!H16:H24,1/KK!I16:I24^2)/SUM(1/KK!I16:I24^2)-SUMPRODUCT('JS YbReRunShifts'!H6:H14,1/'JS YbReRunShifts'!I6:I14^2)/SUM(1/'JS YbReRunShifts'!I6:I14^2) -> #VALUE! | J39: =SUMPRODUCT(KK!J16:J24,1/KK!K16:K24^2)/SUM(1/KK!K16:K24^2)-SUMPRODUCT('JS YbReRunShifts'!J6:J14,1/'JS YbReRunShifts'!K6:K14^2)/SUM(1/'JS YbReRunShifts'!K6:K14^2) -> #VALUE! | L39: =SUMPRODUCT(KK!L16:L24,1/KK!M16:M24^2)/SUM(1/KK!M16:M24^2)-SUMPRODUCT('JS YbReRunShifts'!L6:L14,1/'JS YbReRunShifts'!M6:M14^2)/SUM(1/'JS YbReRunShifts'!M6:M14^2) -> #VALUE! | N39: =AVERAGE(ABS(B39),ABS(D39),ABS(F39),ABS(H39),ABS(J39),ABS(L39)) -> #VALUE! | P39: wm diff | Q39: =SUMPRODUCT(NN!B16:B24,1/NN!C16:C24^2)/SUM(1/NN!C16:C24^2)-SUMPRODUCT('JS YbReRunShifts'!B6:B14,1/'JS YbReRunShifts'!C6:C14^2)/SUM(1/'JS YbReRunShifts'!C6:C14^2) -> #VALUE! | S39: =SUMPRODUCT(NN!D16:D24,1/NN!E16:E24^2)/SUM(1/NN!E16:E24^2)-SUMPRODUCT('JS YbReRunShifts'!D6:D14,1/'JS YbReRunShifts'!E6:E14^2)/SUM(1/'JS YbReRunShifts'!E6:E14^2) -> #VALUE! | U39: =SUMPRODUCT(NN!F16:F24,1/NN!G16:G24^2)/SUM(1/NN!G16:G24^2)-SUMPRODUCT('JS YbReRunShifts'!F6:F14,1/'JS YbReRunShifts'!G6:G14^2)/SUM(1/'JS YbReRunShifts'!G6:G14^2) -> #VALUE! | W39: =SUMPRODUCT(NN!H16:H24,1/NN!I16:I24^2)/SUM(1/NN!I16:I24^2)-SUMPRODUCT('JS YbReRunShifts'!H6:H14,1/'JS YbReRunShifts'!I6:I14^2)/SUM(1/'JS YbReRunShifts'!I6:I14^2) -> #VALUE! | Y39: =SUMPRODUCT(NN!J16:J24,1/NN!K16:K24^2)/SUM(1/NN!K16:K24^2)-SUMPRODUCT('JS YbReRunShifts'!J6:J14,1/'JS YbReRunShifts'!K6:K14^2)/SUM(1/'JS YbReRunShifts'!K6:K14^2) -> #VALUE! | AA39: =SUMPRODUCT(NN!L16:L24,1/NN!M16:M24^2)/SUM(1/NN!M16:M24^2)-SUMPRODUCT('JS YbReRunShifts'!L6:L14,1/'JS YbReRunShifts'!M6:M14^2)/SUM(1/'JS YbReRunShifts'!M6:M14^2) -> #VALUE! | AC39: =AVERAGE(ABS(Q39),ABS(S39),ABS(U39),ABS(W39),ABS(Y39),ABS(AA39)) -> #VALUE!

Sheet ST_diffs
A1: Interpolate nu | B1: ST - KK | E1: ST - NN | H1: ST - JS YbReRunShifts | K1: ST - MCM
B2: Yb/Sr_ErYb | C2: Al/Yb_ErYb | D2: Al/Sr_ErYb | E2: Yb/Sr_ErYb | F2: Al/Yb_ErYb | G2: Al/Sr_ErYb | H2: Yb/Sr_ErYb | I2: Al/Yb_ErYb | J2: Al/Sr_ErYb | K2: Yb/Sr_ErYb | L2: Al/Yb_ErYb | M2: Al/Sr_ErYb
A3: 45673 | B3: =0.0000000000000017787-KK!B12 -> 1.8791966e-15 | C3: =-0.0000000000000019113-KK!F12 -> -1.87978e-15 | D3: =-1.3323E-16-KK!J12 -> 1.97e-18 | E3: =0.0000000000000017787-NN!$B12 -> 1.87913e-15 | F3: =-0.0000000000000019113-NN!$F12 -> -1.876966e-15 | G3: =-1.3323E-16-NN!$J12 -> 1.75e-18 | H3: =0.0000000000000017787-'JS YbReRunShifts'!$B2 -> 1.8790491e-15 | I3: =-0.0000000000000019113-'JS YbReRunShifts'!$F2 -> -1.8768484e-15 | J3: =-1.3323E-16-'JS YbReRunShifts'!$J2 -> 1.8616009e-18
A4: 45681 | B4: =-KK!B13 -> 9.6939414e-17 | C4: =-KK!F13 -> 8.691e-18 | D4: =-KK!J13 -> 1.139e-16 | E4: =-NN!$B13 -> 9.6948e-17 | F4: =-NN!$F13 -> 1.2884e-17 | G4: =-NN!$J13 -> 1.1402e-16 | H4: =-'JS YbReRunShifts'!$B3 -> 9.6596607e-17 | I4: =-'JS YbReRunShifts'!$F3 -> 1.290289e-17 | J4: =-'JS YbReRunShifts'!$J3 -> 1.1406294e-16
A5: 45692 | B5: =-KK!B14 -> 1.047659e-16 | C5: =-KK!F14 -> 1.626e-17 | D5: =-KK!J14 -> 1.265e-16 | E5: =-NN!$B14 -> 1.0455e-16 | F5: =-NN!$F14 -> 2.2251e-17 | G5: =-NN!$J14 -> 1.2569e-16 | H5: =-'JS YbReRunShifts'!$B4 -> 1.0453039e-16 | I5: =-'JS YbReRunShifts'!$F4 -> 2.2347735e-17 | J5: =-'JS YbReRunShifts'!$J4 -> 1.2576081e-16
A6: 45694 | B6: =-KK!B15 -> 1.0302409e-16 | C6: =-KK!F15 -> 1.748e-17 | D6: =-KK!J15 -> 1.28e-16 | E6: =-NN!$B15 -> 1.0297e-16 | F6: =-NN!$F15 -> 2.2105e-17 | G6: =-NN!$J15 -> 1.2805e-16 | H6: =-'JS YbReRunShifts'!$B5 -> 1.0293958e-16 | I6: =-'JS YbReRunShifts'!$F5 -> 2.2216084e-17 | J6: =-'JS YbReRunShifts'!$J5 -> 1.2810471e-16
A7: 45715 | B7: =-KK!B16 -> 1.0713893e-16 | C7: =-KK!F16 -> 1.6184407e-17 | D7: =-KK!J16 -> 1.2304992e-16 | E7: =-NN!$B16 -> 1.0693e-16 | F7: =-NN!$F16 -> 1.6067e-17 | G7: =-NN!$J16 -> 1.2271e-16 | H7: =-'JS YbReRunShifts'!$B6 -> 1.0689003e-16 | I7: =-'JS YbReRunShifts'!$F6 -> 1.6175446e-17 | J7: =-'JS YbReRunShifts'!$J6 -> 1.2278058e-16 | K7: =-MCM!$B16 -> 1.0755e-16 | L7: =-MCM!$F16 -> 1.669e-17 | M7: =-MCM!$J16 -> 1.2311e-16
A8: 45716 | B8: =-KK!B17 -> 1.0257183e-16 | C8: =-KK!F17 -> 1.0455233e-17 | D8: =-KK!J17 -> 1.1392217e-16 | E8: =-NN!$B17 -> 1.0246e-16 | F8: =-NN!$F17 -> 1.0398e-17 | G8: =-NN!$J17 -> 1.1386e-16 | H8: =-'JS YbReRunShifts'!$B7 -> 1.0243451e-16 | I8: =-'JS YbReRunShifts'!$F7 -> 1.0511552e-17 | J8: =-'JS YbReRunShifts'!$J7 -> 1.1378995e-16 | K8: =-MCM!$B17 -> 1.03e-16 | L8: =-MCM!$F17 -> 1.1031e-17 | M8: =-MCM!$J17 -> 1.1457e-16
A9: 45720 | B9: =-KK!B18 -> 1.036598e-16 | C9: =-KK!F18 -> 1.514275e-17 | D9: =-KK!J18 -> 1.1891699e-16 | E9: =-NN!$B18 -> 1.036e-16 | F9: =-NN!$F18 -> 1.517e-17 | G9: =-NN!$J18 -> 1.1888e-16 | H9: =-'JS YbReRunShifts'!$B8 -> 1.0358411e-16 | I9: =-'JS YbReRunShifts'!$F8 -> 1.5278574e-17 | J9: =-'JS YbReRunShifts'!$J8 -> 1.1897136e-16 | K9: =-MCM!$B18 -> 1.0429e-16 | L9: =-MCM!$F18 -> 1.5568e-17 | M9: =-MCM!$J18 -> 1.1944e-16
A10: 45722 | B10: =-KK!B19 -> 1.0431842e-16 | C10: =-KK!F19 -> 1.5396099e-17 | D10: =-KK!J19 -> 1.207086e-16 | E10: =-NN!$B19 -> 1.043e-16 | F10: =-NN!$F19 -> 1.4372e-17 | G10: =-NN!$J19 -> 1.2171e-16 | H10: =-'JS YbReRunShifts'!$B9 -> 1.0426846e-16 | I10: =-'JS YbReRunShifts'!$F9 -> 1.5384074e-17 | J10: =-'JS YbReRunShifts'!$J9 -> 1.2179797e-16 | K10: =-MCM!$B19 -> 1.0507e-16 | L10: =-MCM!$F19 -> 1.5694e-17 | M10: =-MCM!$J19 -> 1.2245e-16
A11: 45723 | B11: =-KK!B20 -> 1.026384e-16 | C11: =-KK!F20 -> 2.4808255e-17 | D11: =-KK!J20 -> 1.2648189e-16 | E11: =-NN!$B20 -> 1.0253e-16 | F11: =-NN!$F20 -> 2.4903e-17 | G11: =-NN!$J20 -> 1.2558e-16 | H11: =-'JS YbReRunShifts'!$B10 -> 1.0248672e-16 | I11: =-'JS YbReRunShifts'!$F10 -> 2.5012426e-17 | J11: =-'JS YbReRunShifts'!$J10 -> 1.2570331e-16 | K11: =-MCM!$B20 -> 1.0318e-16 | L11: =-MCM!$F20 -> 2.542e-17 | M11: =-MCM!$J20 -> 1.2619e-16
A12: 45729 | B12: =-KK!B21 -> 1.0636057e-16 | C12: =-KK!F21 -> 1.45987e-17 | D12: =-KK!J21 -> 1.2040126e-16 | E12: =-NN!$B21 -> 1.0634e-16 | F12: =-NN!$F21 -> 1.4676e-17 | G12: =-NN!$J21 -> 1.2191e-16 | H12: =-'JS YbReRunShifts'!$B11 -> 1.0590373e-16 | I12: =-'JS YbReRunShifts'!$F11 -> 1.4758677e-17 | J12: =-'JS YbReRunShifts'!$J11 -> 1.1953674e-16 | K12: =-MCM!$B21 -> 1.06608e-16 | L12: =-MCM!$F21 -> 1.4987e-17 | M12: =-MCM!$J21 -> 1.2026e-16
A13: 45734 | B13: =-KK!B22 -> 1.0452321e-16 | C13: =-KK!F22 -> 1.5312419e-17 | D13: =-KK!J22 -> 1.1811883e-16 | E13: =-NN!$B22 -> 1.0424e-16 | F13: =-NN!$F22 -> 1.5371e-17 | G13: =-NN!$J22 -> 1.181e-16 | H13: =-'JS YbReRunShifts'!$B12 -> 1.0427039e-16 | I13: =-'JS YbReRunShifts'!$F12 -> 1.5307904e-17 | J13: =-'JS YbReRunShifts'!$J12 -> 1.1816221e-16 | K13: =-MCM!$B22 -> 1.0468e-16 | L13: =-MCM!$F22 -> 1.5762e-17 | M13: =-MCM!$J22 -> 1.1811e-16
A17: Keep missing nu
B18: Yb/Sr_ErYb | C18: Al/Yb_ErYb | D18: Al/Sr_ErYb | E18: Yb/Sr_ErYb | F18: Al/Yb_ErYb | G18: Al/Sr_ErYb | H18: Yb/Sr_ErYb | I18: Al/Yb_ErYb | J18: Al/Sr_ErYb | K18: Yb/Sr_ErYb | L18: Al/Yb_ErYb | M18: Al/Sr_ErYb
A19: 45673 | B19: =0.0000000000000017787-KK!B12 -> 1.8791966e-15 | C19: =-0.0000000000000019113-KK!F12 -> -1.87978e-15 | D19: =-1.3323E-16-KK!J12 -> 1.97e-18 | E19: =0.0000000000000017787-NN!$B12 -> 1.87913e-15 | F19: =-0.0000000000000019113-NN!$F12 -> -1.876966e-15 | G19: =-1.3323E-16-NN!$J12 -> 1.75e-18 | H19: =0.0000000000000017787-'JS YbReRunShifts'!$B2 -> 1.8790491e-15 | I19: =-0.0000000000000019113-'JS YbReRunShifts'!$F2 -> -1.8768484e-15 | J19: =-1.3323E-16-'JS YbReRunShifts'!$J2 -> 1.8616009e-18
A20: 45681 | B20: =-KK!B13 -> 9.6939414e-17 | C20: =-KK!F13 -> 8.691e-18 | D20: =-KK!J13 -> 1.139e-16 | E20: =-NN!$B13 -> 9.6948e-17 | F20: =-NN!$F13 -> 1.2884e-17 | G20: =-NN!$J13 -> 1.1402e-16 | H20: =-'JS YbReRunShifts'!$B3 -> 9.6596607e-17 | I20: =-'JS YbReRunShifts'!$F3 -> 1.290289e-17 | J20: =-'JS YbReRunShifts'!$J3 -> 1.1406294e-16
A21: 45692 | B21: =-KK!B14 -> 1.047659e-16 | C21: =-KK!F14 -> 1.626e-17 | D21: =-KK!J14 -> 1.265e-16 | E21: =-NN!$B14 -> 1.0455e-16 | F21: =-NN!$F14 -> 2.2251e-17 | G21: =-NN!$J14 -> 1.2569e-16 | H21: =-'JS YbReRunShifts'!$B4 -> 1.0453039e-16 | I21: =-'JS YbReRunShifts'!$F4 -> 2.2347735e-17 | J21: =-'JS YbReRunShifts'!$J4 -> 1.2576081e-16
A22: 45694 | B22: =-KK!B15 -> 1.0302409e-16 | C22: =-KK!F15 -> 1.748e-17 | D22: =-KK!J15 -> 1.28e-16 | E22: =-NN!$B15 -> 1.0297e-16 | F22: =-NN!$F15 -> 2.2105e-17 | G22: =-NN!$J15 -> 1.2805e-16 | H22: =-'JS YbReRunShifts'!$B5 -> 1.0293958e-16 | I22: =-'JS YbReRunShifts'!$F5 -> 2.2216084e-17 | J22: =-'JS YbReRunShifts'!$J5 -> 1.2810471e-16
A23: 45715 | B23: =0.0000000000000017697-KK!B16 -> 1.8768389e-15 | C23: =-0.0000000000000018932-KK!F16 -> -1.8770156e-15 | D23: =-1.2359E-16-KK!J16 -> -5.4007786e-19 | E23: =0.0000000000000017697-NN!$B16 -> 1.87663e-15 | F23: =-0.0000000000000018932-NN!$F16 -> -1.877133e-15 | G23: =-1.2359E-16-NN!$J16 -> -8.8e-19 | H23: =0.0000000000000017697-'JS YbReRunShifts'!$B6 -> 1.87659e-15 | I23: =-0.0000000000000018932-'JS YbReRunShifts'!$F6 -> -1.8770246e-15 | J23: =-1.2359E-16-'JS YbReRunShifts'!$J6 -> -8.0941747e-19 | K23: =0.0000000000000017697-MCM!$B16 -> 1.87725e-15 | L23: =-0.0000000000000018932-MCM!$F16 -> -1.87651e-15 | M23: =-MCM!$J16 -> 1.2311e-16
A24: 45716 | B24: =-KK!B17 -> 1.0257183e-16 | C24: =-KK!F17 -> 1.0455233e-17 | D24: =-KK!J17 -> 1.1392217e-16 | E24: =-NN!$B17 -> 1.0246e-16 | F24: =-NN!$F17 -> 1.0398e-17 | G24: =-NN!$J17 -> 1.1386e-16 | H24: =-'JS YbReRunShifts'!$B7 -> 1.0243451e-16 | I24: =-'JS YbReRunShifts'!$F7 -> 1.0511552e-17 | J24: =-'JS YbReRunShifts'!$J7 -> 1.1378995e-16 | K24: =-MCM!$B17 -> 1.03e-16 | L24: =-MCM!$F17 -> 1.1031e-17 | M24: =-MCM!$J17 -> 1.1457e-16
A25: 45720 | B25: =0.0000000000000017728-KK!B18 -> 1.8764598e-15 | C25: =-0.0000000000000018923-KK!F18 -> -1.8771572e-15 | D25: =-1.1975E-16-KK!J18 -> -8.3301419e-19 | E25: =0.0000000000000017728-NN!$B18 -> 1.8764e-15 | F25: =-0.0000000000000018923-NN!$F18 -> -1.87713e-15 | G25: =-1.1975E-16-NN!$J18 -> -8.7e-19 | H25: =0.0000000000000017728-'JS YbReRunShifts'!$B8 -> 1.8763841e-15 | I25: =-0.0000000000000018923-'JS YbReRunShifts'!$F8 -> -1.8770214e-15 | J25: =-1.1975E-16-'JS YbReRunShifts'!$J8 -> -7.7864022e-19 | K25: =0.0000000000000017728-MCM!$B18 -> 1.87709e-15 | L25: =-0.0000000000000018923-MCM!$F18 -> -1.876732e-15 | M25: =-1.1975E-16-MCM!$J18 -> -3.1e-19
A26: 45722 | B26: =-KK!B19 -> 1.0431842e-16 | C26: =-KK!F19 -> 1.5396099e-17 | D26: =-KK!J19 -> 1.207086e-16 | E26: =-NN!$B19 -> 1.043e-16 | F26: =-NN!$F19 -> 1.4372e-17 | G26: =-NN!$J19 -> 1.2171e-16 | H26: =-'JS YbReRunShifts'!$B9 -> 1.0426846e-16 | I26: =-'JS YbReRunShifts'!$F9 -> 1.5384074e-17 | J26: =-'JS YbReRunShifts'!$J9 -> 1.2179797e-16 | K26: =-MCM!$B19 -> 1.0507e-16 | L26: =-MCM!$F19 -> 1.5694e-17 | M26: =-MCM!$J19 -> 1.2245e-16
A27: 45723 | B27: =0.0000000000000017735-KK!B20 -> 1.8761384e-15 | C27: =-0.0000000000000019017-KK!F20 -> -1.8768917e-15 | D27: =-1.2592E-16-KK!J20 -> 5.6188926e-19 | E27: =0.0000000000000017735-NN!$B20 -> 1.87603e-15 | F27: =-0.0000000000000019017-NN!$F20 -> -1.876797e-15 | G27: =-1.2592E-16-NN!$J20 -> -3.4e-19 | H27: =0.0000000000000017735-'JS YbReRunShifts'!$B10 -> 1.8759867e-15 | I27: =-0.0000000000000019017-'JS YbReRunShifts'!$F10 -> -1.8766876e-15 | J27: =-1.2592E-16-'JS YbReRunShifts'!$J10 -> -2.1669169e-19 | K27: =0.0000000000000017735-MCM!$B20 -> 1.87668e-15 | L27: =-0.0000000000000019017-MCM!$F20 -> -1.87628e-15 | M27: =-1.2592E-16-MCM!$J20 -> 2.7e-19
A28: 45729 | B28: =-KK!B21 -> 1.0636057e-16 | C28: =-KK!F21 -> 1.45987e-17 | D28: =-KK!J21 -> 1.2040126e-16 | E28: =-NN!$B21 -> 1.0634e-16 | F28: =-NN!$F21 -> 1.4676e-17 | G28: =-NN!$J21 -> 1.2191e-16 | H28: =-'JS YbReRunShifts'!$B11 -> 1.0590373e-16 | I28: =-'JS YbReRunShifts'!$F11 -> 1.4758677e-17 | J28: =-'JS YbReRunShifts'!$J11 -> 1.1953674e-16 | K28: =-MCM!$B21 -> 1.06608e-16 | L28: =-MCM!$F21 -> 1.4987e-17 | M28: =-MCM!$J21 -> 1.2026e-16
